Workbook

Sheet PF
Q1: PF | R1: PF | S1: PF
G2: PF
J4: GERAL
A6: 0.27222222 | B6: Du's 8 | C6: CAPACITY | D6: TEMPO DISP | E6: DISCAGEM | F6: ATENDIDA | G6: CPC | H6: CPCA | I6: PROPOSTA | J6: PAGAMENTO | K6: ($) CASH | L6: ($) TKT CASH | M6: ($) CONTABIL | N6: ($) TKT CONTABIL | O6: (%) CONVERSÃO | P6: =AUX!B11 -> (%) CPC | Q6: (%) EFETIVIDADE
C7: 9 | D7: =C7*A6 -> 2.45 | E7: 16539 | F7: 308 | G7: =AUX!C2 -> 17 | H7: =AUX!C3 -> 11 | I7: =AUX!C4 -> 2 | J7: =AUX!C5 -> 1 | K7: =AUX!C6 -> 12516.182 | L7: =AUX!C7 -> 5973.63 | M7: =AUX!C8 -> 210239.32 | N7: =AUX!C9 -> 105119.66 | O7: =AUX!C10 -> 0.19 | P7: =AUX!C11 -> 0.56 | Q7: =AUX!C12 -> 0.7
A9: 8 | B9: META GERAL | C9: 7 | D9: =D7*A9 -> 19.6 | E9: =E7*A9 -> 132312 | F9: =F7*A9 -> 2464 | G9: =G7*A9 -> 136 | H9: =H7*A9 -> 88 | I9: =I7*A9 -> 16 | J9: =J7*A9 -> 8 | K9: 357000 | L9: 14236.15 | M9: 5000000 | N9: 103800.73 | O9: =O7 -> 0.19 | P9: =P7 -> 0.56 | Q9: =Q7 -> 0.7
B10: REALIZADO | C10: =AVERAGE(C17:C24) -> 5.774423 | D10: =SUM(D17:D37) -> 12.57541 | E10: =SUM(E17:E37) -> 499351 | F10: =SUM(F17:F37) -> 5455 | G10: =SUM(G17:G37) -> 304 | H10: =SUM(H17:H37) -> 112 | I10: =SUM(I17:I36) -> 20 | J10: =SUM(J17:J36) -> 7 | K10: =SUM(K17:K37) -> 88313.9 | L10: =IFERROR(K10/J10,0) -> 12616.271 | M10: =SUM(M17:M36) -> 283641.89 | N10: =IFERROR(M10/J10,0) -> 40520.27 | O10: =AVERAGE(O17:O36) -> 0.078132481 | P10: =AVERAGE(P17:P24) -> 0.3790389 | Q10: =IFERROR(AVERAGE(Q17:Q36),0) -> 0.58333333
B11: META RELOGIO | C11: - | D11: =D7*(COUNTIFS(D17:D36,">="&0)) -> 49 | E11: =E7*(COUNTIFS(E17:E34,">="&1)) -> 132312 | F11: =F7*(COUNTIFS(F17:F34,">="&1)) -> 2464 | G11: =G7*(COUNTIFS(G17:G37,">="&1)) -> 136 | H11: =H7*(COUNTIFS(H17:H34,">="&1)) -> 88 | I11: =I7*(COUNTIFS(I17:I34,">="&1)) -> 14 | J11: =J7*(COUNTIFS(J17:J34,">="&1)) -> 5 | K11: =K7*(COUNTIFS(G17:G34,">="&1)) -> 100129.46 | L11: =L9 -> 14236.15 | M11: =M7*(COUNTIFS(G17:G29,">="&1)) -> 1681914.6 | N11: =N9 -> 103800.73 | O11: =O9 -> 0.19 | P11: =P9 -> 0.56 | Q11: =Q9 -> 0.7
B13: (%) META REALIZADO | C13: =C10/C9 -> 0.82491757 | D13: =D10/D9 -> 0.64160255 | E13: =E10/E9 -> 3.7740417 | F13: =F10/F9 -> 2.2138799 | G13: =G10/G9 -> 2.2352941 | H13: =H10/H9 -> 1.2727273 | I13: =I10/I9 -> 1.25 | J13: =J10/J9 -> 0.875 | ... P13: =P10/P9 -> 0.67685518 | Q13: =IFERROR(Q10/Q9,0) -> 0.83333333
B14: (%) META RELOGIO | C14: - | D14: =D10/D11 -> 0.25664102 | E14: =E10/E11 -> 3.7740417 | F14: =F10/F11 -> 2.2138799 | G14: =G10/G11 -> 2.2352941 | H14: =H10/H11 -> 1.2727273 | I14: =I10/I11 -> 1.4285714 | J14: =IFERROR(J10/J11,0) -> 1.4 | K14: =K10/K11 -> 0.88199717 | L14: =L10/L11 -> 0.88621372 | M14: =M10/M11 -> 0.16864227 | N14: =N10/N11 -> 0.39036594 | O14: =O10/O11 -> 0.41122358 | P14: =P10/P9 -> 0.67685518 | Q14: =IFERROR(Q10/Q9,0) -> 0.83333333
B16: DATA | C16: REALIZADO | D16: TEMPO REALIZADO | E16: DISCAGEM | F16: ATENDIDA | G16: CPC | H16: CPCA | I16: PROPOSTA | J16: PAGAMENTO | K16: ($) CASH | L16: ($) TKT CASH | M16: ($) CONTABIL | N16: ($) TKT CONTABIL | O16: (%) CONVERSÃO | P16: (%) CPC | Q16: (%) EFETIVIDADE
B17: 46266 | C17: =D17/$A$6 -> 5.3086776 | D17: =SUMIFS(TEMPOS!AL:AL,TEMPOS!X:X,PF!$Q$1,TEMPOS!Y:Y,B17) -> 1.44514 | E17: =SUMIFS('HORA HORA'!G:G,'HORA HORA'!C:C,PF!$S$1,'HORA HORA'!B:B,PF!B17) -> 49688 | F17: =SUMIFS('HORA HORA'!H:H,'HORA HORA'!B:B,PF!B17,'HORA HORA'!C:C,PF!$S$1) -> 631 | G17: =SUMIFS('HORA HORA'!J:J,'HORA HORA'!C:C,PF!$G$2,'HORA HORA'!B:B,B17,'HORA HORA'!C:C,PF!$G$2) -> 44 | H17: =SUMIFS('HORA HORA'!K:K,'HORA HORA'!C:C,PF!$G$2,'HORA HORA'!B:B,B17,'HORA HORA'!C:C,PF!$G$2) -> 14 | I17: =SUMIFS('HORA HORA'!L:L,'HORA HORA'!C:C,PF!$G$2,'HORA HORA'!B:B,B17,'HORA HORA'!C:C,PF!$G$2) -> 1 | J17: =COUNTIFS(ACOMPANHAMENTO!S:S,"ACORDO IMPLANTADO",ACOMPANHAMENTO!BC:BC,B17,ACOMPANHAMENTO!H:H,PF!$G$2) -> 0 | K17: =SUMIFS(ACOMPANHAMENTO!O:O,ACOMPANHAMENTO!H:H,PF!$G$2,ACOMPANHAMENTO!BC:BC,B17) -> 0 | L17: =K17/I17 -> 0 | M17: =SUMIFS(ACOMPANHAMENTO!R:R,ACOMPANHAMENTO!H:H,PF!$G$2,ACOMPANHAMENTO!BC:BC,PF!B17) -> 0 | N17: =M17/I17 -> 0 | O17: =IFERROR(IF(I17/G17=0,"-",I17/G17),"-") -> 0.022727273 | P17: =SUMIFS('HORA HORA'!$K:$K,'HORA HORA'!$B:$B,$B17,'HORA HORA'!$C:$C,"="&"PF")/SUMIFS('HORA HORA'!$J:$J,'HORA HORA'!$B:$B,PF!$B17,'HORA HORA'!$C:$C,$G$2) -> 0.31818182 | Q17: =IFERROR(IF(J17/I17=0,"-",J17/I17),"-") -> -
B18: 46267 | C18: =D18/$A$6 -> 7.1256784 | D18: =SUMIFS(TEMPOS!AL:AL,TEMPOS!X:X,PF!$Q$1,TEMPOS!Y:Y,B18) -> 1.939768 | E18: =SUMIFS('HORA HORA'!G:G,'HORA HORA'!C:C,PF!$S$1,'HORA HORA'!B:B,PF!B18) -> 66752 | F18: =SUMIFS('HORA HORA'!H:H,'HORA HORA'!B:B,PF!B18,'HORA HORA'!C:C,PF!$S$1) -> 699 | G18: =SUMIFS('HORA HORA'!J:J,'HORA HORA'!C:C,PF!$G$2,'HORA HORA'!B:B,B18,'HORA HORA'!C:C,PF!$G$2) -> 49 | H18: =SUMIFS('HORA HORA'!K:K,'HORA HORA'!C:C,PF!$G$2,'HORA HORA'!B:B,B18,'HORA HORA'!C:C,PF!$G$2) -> 14 | I18: =SUMIFS('HORA HORA'!L:L,'HORA HORA'!C:C,PF!$G$2,'HORA HORA'!B:B,B18,'HORA HORA'!C:C,PF!$G$2) -> 4 | J18: =COUNTIFS(ACOMPANHAMENTO!S:S,"ACORDO IMPLANTADO",ACOMPANHAMENTO!BC:BC,B18,ACOMPANHAMENTO!H:H,PF!$G$2) -> 0 | K18: =SUMIFS(ACOMPANHAMENTO!O:O,ACOMPANHAMENTO!H:H,PF!$G$2,ACOMPANHAMENTO!BC:BC,B18) -> 0 | L18: =IFERROR(K18/I18,0) -> 0 | M18: =SUMIFS(ACOMPANHAMENTO!R:R,ACOMPANHAMENTO!H:H,PF!$G$2,ACOMPANHAMENTO!BC:BC,PF!B18) -> 0 | N18: =IFERROR(M18/I18,0) -> 0 | O18: =IFERROR(IF(I18/G18=0,"-",I18/G18),"-") -> 0.081632653 | P18: =IFERROR(SUMIFS('HORA HORA'!$K:$K,'HORA HORA'!$B:$B,$B18,'HORA HORA'!$C:$C,"="&"PF")/SUMIFS('HORA HORA'!$J:$J,'HORA HORA'!$B:$B,PF!$B18,'HORA HORA'!$C:$C,$G$2),0) -> 0.28571429 | Q18: =IFERROR(IF(J18/I18=0,"-",J18/I18),"-") -> -
B19: 46268 | C19: =D19/$A$6 -> 6.1508094 | D19: =SUMIFS(TEMPOS!AL:AL,TEMPOS!X:X,PF!$Q$1,TEMPOS!Y:Y,B19) -> 1.674387 | E19: =SUMIFS('HORA HORA'!G:G,'HORA HORA'!C:C,PF!$S$1,'HORA HORA'!B:B,PF!B19) -> 65425 | F19: =SUMIFS('HORA HORA'!H:H,'HORA HORA'!B:B,PF!B19,'HORA HORA'!C:C,PF!$S$1) -> 644 | G19: =SUMIFS('HORA HORA'!J:J,'HORA HORA'!C:C,PF!$G$2,'HORA HORA'!B:B,B19,'HORA HORA'!C:C,PF!$G$2) -> 40 | H19: =SUMIFS('HORA HORA'!K:K,'HORA HORA'!C:C,PF!$G$2,'HORA HORA'!B:B,B19,'HORA HORA'!C:C,PF!$G$2) -> 10 | I19: =SUMIFS('HORA HORA'!L:L,'HORA HORA'!C:C,PF!$G$2,'HORA HORA'!B:B,B19,'HORA HORA'!C:C,PF!$G$2) -> 2 | J19: =COUNTIFS(ACOMPANHAMENTO!S:S,"ACORDO IMPLANTADO",ACOMPANHAMENTO!BC:BC,B19,ACOMPANHAMENTO!H:H,PF!$G$2) -> 0 | K19: =SUMIFS(ACOMPANHAMENTO!O:O,ACOMPANHAMENTO!H:H,PF!$G$2,ACOMPANHAMENTO!BC:BC,B19) -> 0 | L19: =IFERROR(K19/I19,0) -> 0 | M19: =SUMIFS(ACOMPANHAMENTO!R:R,ACOMPANHAMENTO!H:H,PF!$G$2,ACOMPANHAMENTO!BC:BC,PF!B19) -> 0 | N19: =IFERROR(M19/I19,0) -> 0 | O19: =IFERROR(IF(I19/G19=0,"-",I19/G19),"-") -> 0.05 | P19: =IFERROR(SUMIFS('HORA HORA'!$K:$K,'HORA HORA'!$B:$B,$B19,'HORA HORA'!$C:$C,"="&"PF")/SUMIFS('HORA HORA'!$J:$J,'HORA HORA'!$B:$B,PF!$B19,'HORA HORA'!$C:$C,$G$2),0) -> 0.25 | Q19: =IFERROR(IF(J19/I19=0,"-",J19/I19),"-") -> -
B20: 46269 | C20: =D20/$A$6 -> 6.9091457 | D20: =SUMIFS(TEMPOS!AL:AL,TEMPOS!X:X,PF!$Q$1,TEMPOS!Y:Y,B20) -> 1.880823 | E20: =SUMIFS('HORA HORA'!G:G,'HORA HORA'!C:C,PF!$S$1,'HORA HORA'!B:B,PF!B20) -> 67901 | F20: =SUMIFS('HORA HORA'!H:H,'HORA HORA'!B:B,PF!B20,'HORA HORA'!C:C,PF!$S$1) -> 659 | G20: =SUMIFS('HORA HORA'!J:J,'HORA HORA'!C:C,PF!$G$2,'HORA HORA'!B:B,B20,'HORA HORA'!C:C,PF!$G$2) -> 31 | H20: =SUMIFS('HORA HORA'!K:K,'HORA HORA'!C:C,PF!$G$2,'HORA HORA'!B:B,B20,'HORA HORA'!C:C,PF!$G$2) -> 12 | I20: =SUMIFS('HORA HORA'!L:L,'HORA HORA'!C:C,PF!$G$2,'HORA HORA'!B:B,B20,'HORA HORA'!C:C,PF!$G$2) -> 4 | J20: =COUNTIFS(ACOMPANHAMENTO!S:S,"ACORDO IMPLANTADO",ACOMPANHAMENTO!BC:BC,B20,ACOMPANHAMENTO!H:H,PF!$G$2) -> 1 | K20: =SUMIFS(ACOMPANHAMENTO!O:O,ACOMPANHAMENTO!H:H,PF!$G$2,ACOMPANHAMENTO!BC:BC,B20) -> 5000 | L20: =IFERROR(K20/I20,0) -> 1250 | M20: =SUMIFS(ACOMPANHAMENTO!R:R,ACOMPANHAMENTO!H:H,PF!$G$2,ACOMPANHAMENTO!BC:BC,PF!B20) -> 0 | N20: =IFERROR(M20/I20,0) -> 0 | O20: =IFERROR(IF(I20/G20=0,"-",I20/G20),"-") -> 0.12903226 | P20: =IFERROR(SUMIFS('HORA HORA'!$K:$K,'HORA HORA'!$B:$B,$B20,'HORA HORA'!$C:$C,"="&"PF")/SUMIFS('HORA HORA'!$J:$J,'HORA HORA'!$B:$B,PF!$B20,'HORA HORA'!$C:$C,$G$2),0) -> 0.38709677 | Q20: =IFERROR(IF(J20/I20=0,"-",J20/I20),"-") -> 0.25
B21: 46273 | C21: =D21/$A$6 -> 6.5947776 | D21: =SUMIFS(TEMPOS!AL:AL,TEMPOS!X:X,PF!$Q$1,TEMPOS!Y:Y,B21) -> 1.795245 | E21: =SUMIFS('HORA HORA'!G:G,'HORA HORA'!C:C,PF!$S$1,'HORA HORA'!B:B,PF!B21) -> 59736 | F21: =SUMIFS('HORA HORA'!H:H,'HORA HORA'!B:B,PF!B21,'HORA HORA'!C:C,PF!$S$1) -> 640 | G21: =SUMIFS('HORA HORA'!J:J,'HORA HORA'!C:C,PF!$G$2,'HORA HORA'!B:B,B21,'HORA HORA'!C:C,PF!$G$2) -> 31 | H21: =SUMIFS('HORA HORA'!K:K,'HORA HORA'!C:C,PF!$G$2,'HORA HORA'!B:B,B21,'HORA HORA'!C:C,PF!$G$2) -> 20 | I21: =SUMIFS('HORA HORA'!L:L,'HORA HORA'!C:C,PF!$G$2,'HORA HORA'!B:B,B21,'HORA HORA'!C:C,PF!$G$2) -> 4 | J21: =COUNTIFS(ACOMPANHAMENTO!S:S,"ACORDO IMPLANTADO",ACOMPANHAMENTO!BC:BC,B21,ACOMPANHAMENTO!H:H,PF!$G$2) -> 1 | K21: =SUMIFS(ACOMPANHAMENTO!O:O,ACOMPANHAMENTO!H:H,PF!$G$2,ACOMPANHAMENTO!BC:BC,B21) -> 7735.51 | L21: =IFERROR(K21/I21,0) -> 1933.8775 | M21: =SUMIFS(ACOMPANHAMENTO!R:R,ACOMPANHAMENTO!H:H,PF!$G$2,ACOMPANHAMENTO!BC:BC,PF!B21) -> 69713.73 | N21: =IFERROR(M21/I21,0) -> 17428.432 | O21: =IFERROR(IF(I21/G21=0,"-",I21/G21),"-") -> 0.12903226 | P21: =IFERROR(SUMIFS('HORA HORA'!$K:$K,'HORA HORA'!$B:$B,$B21,'HORA HORA'!$C:$C,"="&"PF")/SUMIFS('HORA HORA'!$J:$J,'HORA HORA'!$B:$B,PF!$B21,'HORA HORA'!$C:$C,$G$2),0) -> 0.64516129 | Q21: =IFERROR(IF(J21/I21=0,"-",J21/I21),"-") -> 0.25
B22: 46274 | C22: =D22/$A$6 -> 6.9705808 | D22: =SUMIFS(TEMPOS!AL:AL,TEMPOS!X:X,PF!$Q$1,TEMPOS!Y:Y,B22) -> 1.897547 | E22: =SUMIFS('HORA HORA'!G:G,'HORA HORA'!C:C,PF!$S$1,'HORA HORA'!B:B,PF!B22) -> 61385 | F22: =SUMIFS('HORA HORA'!H:H,'HORA HORA'!B:B,PF!B22,'HORA HORA'!C:C,PF!$S$1) -> 810 | G22: =SUMIFS('HORA HORA'!J:J,'HORA HORA'!C:C,PF!$G$2,'HORA HORA'!B:B,B22,'HORA HORA'!C:C,PF!$G$2) -> 36 | H22: =SUMIFS('HORA HORA'!K:K,'HORA HORA'!C:C,PF!$G$2,'HORA HORA'!B:B,B22,'HORA HORA'!C:C,PF!$G$2) -> 11 | I22: =SUMIFS('HORA HORA'!L:L,'HORA HORA'!C:C,PF!$G$2,'HORA HORA'!B:B,B22,'HORA HORA'!C:C,PF!$G$2) -> 2 | J22: =COUNTIFS(ACOMPANHAMENTO!S:S,"ACORDO IMPLANTADO",ACOMPANHAMENTO!BC:BC,B22,ACOMPANHAMENTO!H:H,PF!$G$2) -> 3 | K22: =SUMIFS(ACOMPANHAMENTO!O:O,ACOMPANHAMENTO!H:H,PF!$G$2,ACOMPANHAMENTO!BC:BC,B22) -> 50446.06 | L22: =IFERROR(K22/I22,0) -> 25223.03 | M22: =SUMIFS(ACOMPANHAMENTO!R:R,ACOMPANHAMENTO!H:H,PF!$G$2,ACOMPANHAMENTO!BC:BC,PF!B22) -> 91192.87 | N22: =IFERROR(M22/I22,0) -> 45596.435 | O22: =IFERROR(IF(I22/G22=0,"-",I22/G22),"-") -> 0.055555556 | P22: =IFERROR(SUMIFS('HORA HORA'!$K:$K,'HORA HORA'!$B:$B,$B22,'HORA HORA'!$C:$C,"="&"PF")/SUMIFS('HORA HORA'!$J:$J,'HORA HORA'!$B:$B,PF!$B22,'HORA HORA'!$C:$C,$G$2),0) -> 0.30555556 | Q22: =IFERROR(IF(J22/I22=0,"-",J22/I22),"-") -> 1.5
B23: 46275 | C23: =D23/$A$6 -> 7.1357143 | D23: =SUMIFS(TEMPOS!AL:AL,TEMPOS!X:X,PF!$Q$1,TEMPOS!Y:Y,B23) -> 1.9425 | E23: =SUMIFS('HORA HORA'!G:G,'HORA HORA'!C:C,PF!$S$1,'HORA HORA'!B:B,PF!B23) -> 60597 | F23: =SUMIFS('HORA HORA'!H:H,'HORA HORA'!B:B,PF!B23,'HORA HORA'!C:C,PF!$S$1) -> 656 | G23: =SUMIFS('HORA HORA'!J:J,'HORA HORA'!C:C,PF!$G$2,'HORA HORA'!B:B,B23,'HORA HORA'!C:C,PF!$G$2) -> 35 | H23: =SUMIFS('HORA HORA'!K:K,'HORA HORA'!C:C,PF!$G$2,'HORA HORA'!B:B,B23,'HORA HORA'!C:C,PF!$G$2) -> 11 | I23: =SUMIFS('HORA HORA'!L:L,'HORA HORA'!C:C,PF!$G$2,'HORA HORA'!B:B,B23,'HORA HORA'!C:C,PF!$G$2) -> 0 | J23: =COUNTIFS(ACOMPANHAMENTO!S:S,"ACORDO IMPLANTADO",ACOMPANHAMENTO!BC:BC,B23,ACOMPANHAMENTO!H:H,PF!$G$2) -> 1 | K23: =SUMIFS(ACOMPANHAMENTO!O:O,ACOMPANHAMENTO!H:H,PF!$G$2,ACOMPANHAMENTO!BC:BC,B23) -> 132.32 | L23: =IFERROR(K23/I23,0) -> 0 | M23: =SUMIFS(ACOMPANHAMENTO!R:R,ACOMPANHAMENTO!H:H,PF!$G$2,ACOMPANHAMENTO!BC:BC,PF!B23) -> 5970.05 | N23: =IFERROR(M23/I23,0) -> 0 | O23: =IFERROR(IF(I23/G23=0,"-",I23/G23),"-") -> - | P23: =IFERROR(SUMIFS('HORA HORA'!$K:$K,'HORA HORA'!$B:$B,$B23,'HORA HORA'!$C:$C,"="&"PF")/SUMIFS('HORA HORA'!$J:$J,'HORA HORA'!$B:$B,PF!$B23,'HORA HORA'!$C:$C,$G$2),0) -> 0.31428571 | Q23: =IFERROR(IF(J23/I23=0,"-",J23/I23),"-") -> -
B24: 46276 | C24: =D24/$A$6 -> 0 | D24: =SUMIFS(TEMPOS!AL:AL,TEMPOS!X:X,PF!$Q$1,TEMPOS!Y:Y,B24) -> 0 | E24: =SUMIFS('HORA HORA'!G:G,'HORA HORA'!C:C,PF!$S$1,'HORA HORA'!B:B,PF!B24) -> 67867 | F24: =SUMIFS('HORA HORA'!H:H,'HORA HORA'!B:B,PF!B24,'HORA HORA'!C:C,PF!$S$1) -> 716 | G24: =SUMIFS('HORA HORA'!J:J,'HORA HORA'!C:C,PF!$G$2,'HORA HORA'!B:B,B24,'HORA HORA'!C:C,PF!$G$2) -> 38 | H24: =SUMIFS('HORA HORA'!K:K,'HORA HORA'!C:C,PF!$G$2,'HORA HORA'!B:B,B24,'HORA HORA'!C:C,PF!$G$2) -> 20 | I24: =SUMIFS('HORA HORA'!L:L,'HORA HORA'!C:C,PF!$G$2,'HORA HORA'!B:B,B24,'HORA HORA'!C:C,PF!$G$2) -> 3 | J24: =COUNTIFS(ACOMPANHAMENTO!S:S,"ACORDO IMPLANTADO",ACOMPANHAMENTO!BC:BC,B24,ACOMPANHAMENTO!H:H,PF!$G$2) -> 1 | K24: =SUMIFS(ACOMPANHAMENTO!O:O,ACOMPANHAMENTO!H:H,PF!$G$2,ACOMPANHAMENTO!BC:BC,B24) -> 25000.01 | L24: =IFERROR(K24/I24,0) -> 8333.3367 | M24: =SUMIFS(ACOMPANHAMENTO!R:R,ACOMPANHAMENTO!H:H,PF!$G$2,ACOMPANHAMENTO!BC:BC,PF!B24) -> 116765.24 | N24: =IFERROR(M24/I24,0) -> 38921.747 | O24: =IFERROR(IF(I24/G24=0,"-",I24/G24),"-") -> 0.078947368 | P24: =IFERROR(SUMIFS('HORA HORA'!$K:$K,'HORA HORA'!$B:$B,$B24,'HORA HORA'!$C:$C,"="&"PF")/SUMIFS('HORA HORA'!$J:$J,'HORA HORA'!$B:$B,PF!$B24,'HORA HORA'!$C:$C,$G$2),0) -> 0.52631579 | Q24: =IFERROR(IF(J24/I24=0,"-",J24/I24),"-") -> 0.33333333
B25: 46279 | C25: =D25/$A$6 -> 0 | D25: =SUMIFS(TEMPOS!AL:AL,TEMPOS!X:X,PF!$Q$1,TEMPOS!Y:Y,B25) -> 0 | E25: =SUMIFS('HORA HORA'!G:G,'HORA HORA'!C:C,PF!$S$1,'HORA HORA'!B:B,PF!B25) -> 0 | F25: =SUMIFS('HORA HORA'!H:H,'HORA HORA'!B:B,PF!B25,'HORA HORA'!C:C,PF!$S$1) -> 0 | G25: =SUMIFS('HORA HORA'!J:J,'HORA HORA'!C:C,PF!$G$2,'HORA HORA'!B:B,B25,'HORA HORA'!C:C,PF!$G$2) -> 0 | H25: =SUMIFS('HORA HORA'!K:K,'HORA HORA'!C:C,PF!$G$2,'HORA HORA'!B:B,B25,'HORA HORA'!C:C,PF!$G$2) -> 0 | I25: =SUMIFS('HORA HORA'!L:L,'HORA HORA'!C:C,PF!$G$2,'HORA HORA'!B:B,B25,'HORA HORA'!C:C,PF!$G$2) -> 0 | J25: =COUNTIFS(ACOMPANHAMENTO!S:S,"ACORDO IMPLANTADO",ACOMPANHAMENTO!BC:BC,B25,ACOMPANHAMENTO!H:H,PF!$G$2) -> 0 | K25: =SUMIFS(ACOMPANHAMENTO!O:O,ACOMPANHAMENTO!H:H,PF!$G$2,ACOMPANHAMENTO!BC:BC,B25) -> 0 | L25: =IFERROR(K25/I25,0) -> 0 | M25: =SUMIFS(ACOMPANHAMENTO!R:R,ACOMPANHAMENTO!H:H,PF!$G$2,ACOMPANHAMENTO!BC:BC,PF!B25) -> 0 | N25: =IFERROR(M25/I25,0) -> 0 | O25: =IFERROR(IF(I25/G25=0,"-",I25/G25),"-") -> - | P25: =IFERROR(SUMIFS('HORA HORA'!$K:$K,'HORA HORA'!$B:$B,$B25,'HORA HORA'!$C:$C,"="&"PF")/SUMIFS('HORA HORA'!$J:$J,'HORA HORA'!$B:$B,PF!$B25,'HORA HORA'!$C:$C,$G$2),0) -> 0 | Q25: =IFERROR(IF(J25/I25=0,"-",J25/I25),"-") -> -
B26: 46280 | C26: =D26/$A$6 -> 0 | D26: =SUMIFS(TEMPOS!AL:AL,TEMPOS!X:X,PF!$Q$1,TEMPOS!Y:Y,B26) -> 0 | E26: =SUMIFS('HORA HORA'!G:G,'HORA HORA'!C:C,PF!$S$1,'HORA HORA'!B:B,PF!B26) -> 0 | F26: =SUMIFS('HORA HORA'!H:H,'HORA HORA'!B:B,PF!B26,'HORA HORA'!C:C,PF!$S$1) -> 0 | G26: =SUMIFS('HORA HORA'!J:J,'HORA HORA'!C:C,PF!$G$2,'HORA HORA'!B:B,B26,'HORA HORA'!C:C,PF!$G$2) -> 0 | H26: =SUMIFS('HORA HORA'!K:K,'HORA HORA'!C:C,PF!$G$2,'HORA HORA'!B:B,B26,'HORA HORA'!C:C,PF!$G$2) -> 0 | I26: =SUMIFS('HORA HORA'!L:L,'HORA HORA'!C:C,PF!$G$2,'HORA HORA'!B:B,B26,'HORA HORA'!C:C,PF!$G$2) -> 0 | J26: =COUNTIFS(ACOMPANHAMENTO!S:S,"ACORDO IMPLANTADO",ACOMPANHAMENTO!BC:BC,B26,ACOMPANHAMENTO!H:H,PF!$G$2) -> 0 | K26: =SUMIFS(ACOMPANHAMENTO!O:O,ACOMPANHAMENTO!H:H,PF!$G$2,ACOMPANHAMENTO!BC:BC,B26) -> 0 | L26: =IFERROR(K26/I26,0) -> 0 | M26: =SUMIFS(ACOMPANHAMENTO!R:R,ACOMPANHAMENTO!H:H,PF!$G$2,ACOMPANHAMENTO!BC:BC,PF!B26) -> 0 | N26: =IFERROR(M26/I26,0) -> 0 | O26: =IFERROR(IF(I26/G26=0,"-",I26/G26),"-") -> - | P26: =IFERROR(SUMIFS('HORA HORA'!$K:$K,'HORA HORA'!$B:$B,$B26,'HORA HORA'!$C:$C,"="&"PF")/SUMIFS('HORA HORA'!$J:$J,'HORA HORA'!$B:$B,PF!$B26,'HORA HORA'!$C:$C,$G$2),0) -> 0 | Q26: =IFERROR(IF(J26/I26=0,"-",J26/I26),"-") -> -
B27: 46281 | C27: =D27/$A$6 -> 0 | D27: =SUMIFS(TEMPOS!AL:AL,TEMPOS!X:X,PF!$Q$1,TEMPOS!Y:Y,B27) -> 0 | E27: =SUMIFS('HORA HORA'!G:G,'HORA HORA'!C:C,PF!$S$1,'HORA HORA'!B:B,PF!B27) -> 0 | F27: =SUMIFS('HORA HORA'!H:H,'HORA HORA'!B:B,PF!B27,'HORA HORA'!C:C,PF!$S$1) -> 0 | G27: =SUMIFS('HORA HORA'!J:J,'HORA HORA'!C:C,PF!$G$2,'HORA HORA'!B:B,B27,'HORA HORA'!C:C,PF!$G$2) -> 0 | H27: =SUMIFS('HORA HORA'!K:K,'HORA HORA'!C:C,PF!$G$2,'HORA HORA'!B:B,B27,'HORA HORA'!C:C,PF!$G$2) -> 0 | I27: =SUMIFS('HORA HORA'!L:L,'HORA HORA'!C:C,PF!$G$2,'HORA HORA'!B:B,B27,'HORA HORA'!C:C,PF!$G$2) -> 0 | J27: =COUNTIFS(ACOMPANHAMENTO!S:S,"ACORDO IMPLANTADO",ACOMPANHAMENTO!BC:BC,B27,ACOMPANHAMENTO!H:H,PF!$G$2) -> 0 | K27: =SUMIFS(ACOMPANHAMENTO!O:O,ACOMPANHAMENTO!H:H,PF!$G$2,ACOMPANHAMENTO!BC:BC,B27) -> 0 | L27: =IFERROR(K27/I27,0) -> 0 | M27: =SUMIFS(ACOMPANHAMENTO!R:R,ACOMPANHAMENTO!H:H,PF!$G$2,ACOMPANHAMENTO!BC:BC,PF!B27) -> 0 | N27: =IFERROR(M27/I27,0) -> 0 | O27: =IFERROR(IF(I27/G27=0,"-",I27/G27),"-") -> - | P27: =IFERROR(SUMIFS('HORA HORA'!$K:$K,'HORA HORA'!$B:$B,$B27,'HORA HORA'!$C:$C,"="&"PF")/SUMIFS('HORA HORA'!$J:$J,'HORA HORA'!$B:$B,PF!$B27,'HORA HORA'!$C:$C,$G$2),0) -> 0 | Q27: =IFERROR(IF(J27/I27=0,"-",J27/I27),"-") -> -
B28: 46282 | C28: =D28/$A$6 -> 0 | D28: =SUMIFS(TEMPOS!AL:AL,TEMPOS!X:X,PF!$Q$1,TEMPOS!Y:Y,B28) -> 0 | E28: =SUMIFS('HORA HORA'!G:G,'HORA HORA'!C:C,PF!$S$1,'HORA HORA'!B:B,PF!B28) -> 0 | F28: =SUMIFS('HORA HORA'!H:H,'HORA HORA'!B:B,PF!B28,'HORA HORA'!C:C,PF!$S$1) -> 0 | G28: =SUMIFS('HORA HORA'!J:J,'HORA HORA'!C:C,PF!$G$2,'HORA HORA'!B:B,B28,'HORA HORA'!C:C,PF!$G$2) -> 0 | H28: =SUMIFS('HORA HORA'!K:K,'HORA HORA'!C:C,PF!$G$2,'HORA HORA'!B:B,B28,'HORA HORA'!C:C,PF!$G$2) -> 0 | I28: =SUMIFS('HORA HORA'!L:L,'HORA HORA'!C:C,PF!$G$2,'HORA HORA'!B:B,B28,'HORA HORA'!C:C,PF!$G$2) -> 0 | J28: =COUNTIFS(ACOMPANHAMENTO!S:S,"ACORDO IMPLANTADO",ACOMPANHAMENTO!BC:BC,B28,ACOMPANHAMENTO!H:H,PF!$G$2) -> 0 | K28: =SUMIFS(ACOMPANHAMENTO!O:O,ACOMPANHAMENTO!H:H,PF!$G$2,ACOMPANHAMENTO!BC:BC,B28) -> 0 | L28: =IFERROR(K28/I28,0) -> 0 | M28: =SUMIFS(ACOMPANHAMENTO!R:R,ACOMPANHAMENTO!H:H,PF!$G$2,ACOMPANHAMENTO!BC:BC,PF!B28) -> 0 | N28: =IFERROR(M28/I28,0) -> 0 | O28: =IFERROR(IF(I28/G28=0,"-",I28/G28),"-") -> - | P28: =IFERROR(SUMIFS('HORA HORA'!$K:$K,'HORA HORA'!$B:$B,$B28,'HORA HORA'!$C:$C,"="&"PF")/SUMIFS('HORA HORA'!$J:$J,'HORA HORA'!$B:$B,PF!$B28,'HORA HORA'!$C:$C,$G$2),0) -> 0 | Q28: =IFERROR(IF(J28/I28=0,"-",J28/I28),"-") -> -
B29: 46283 | C29: =D29/$A$6 -> 0 | D29: =SUMIFS(TEMPOS!AL:AL,TEMPOS!X:X,PF!$Q$1,TEMPOS!Y:Y,B29) -> 0 | E29: =SUMIFS('HORA HORA'!G:G,'HORA HORA'!C:C,PF!$S$1,'HORA HORA'!B:B,PF!B29) -> 0 | F29: =SUMIFS('HORA HORA'!H:H,'HORA HORA'!B:B,PF!B29,'HORA HORA'!C:C,PF!$S$1) -> 0 | G29: =SUMIFS('HORA HORA'!J:J,'HORA HORA'!C:C,PF!$G$2,'HORA HORA'!B:B,B29,'HORA HORA'!C:C,PF!$G$2) -> 0 | H29: =SUMIFS('HORA HORA'!K:K,'HORA HORA'!C:C,PF!$G$2,'HORA HORA'!B:B,B29,'HORA HORA'!C:C,PF!$G$2) -> 0 | I29: =SUMIFS('HORA HORA'!L:L,'HORA HORA'!C:C,PF!$G$2,'HORA HORA'!B:B,B29,'HORA HORA'!C:C,PF!$G$2) -> 0 | J29: =COUNTIFS(ACOMPANHAMENTO!S:S,"ACORDO IMPLANTADO",ACOMPANHAMENTO!BC:BC,B29,ACOMPANHAMENTO!H:H,PF!$G$2) -> 0 | K29: =SUMIFS(ACOMPANHAMENTO!O:O,ACOMPANHAMENTO!H:H,PF!$G$2,ACOMPANHAMENTO!BC:BC,B29) -> 0 | L29: =IFERROR(K29/I29,0) -> 0 | M29: =SUMIFS(ACOMPANHAMENTO!R:R,ACOMPANHAMENTO!H:H,PF!$G$2,ACOMPANHAMENTO!BC:BC,PF!B29) -> 0 | N29: =IFERROR(M29/I29,0) -> 0 | O29: =IFERROR(IF(I29/G29=0,"-",I29/G29),"-") -> - | P29: =IFERROR(SUMIFS('HORA HORA'!$K:$K,'HORA HORA'!$B:$B,$B29,'HORA HORA'!$C:$C,"="&"PF")/SUMIFS('HORA HORA'!$J:$J,'HORA HORA'!$B:$B,PF!$B29,'HORA HORA'!$C:$C,$G$2),0) -> 0 | Q29: =IFERROR(IF(J29/I29=0,"-",J29/I29),"-") -> -
... B37: 46295 | C37: =D37/$A$6 -> 0 | D37: =SUMIFS(TEMPOS!AL:AL,TEMPOS!X:X,PF!$Q$1,TEMPOS!Y:Y,B37) -> 0 | E37: =SUMIFS('HORA HORA'!G:G,'HORA HORA'!C:C,PF!$S$1,'HORA HORA'!B:B,PF!B37) -> 0 | F37: =SUMIFS('HORA HORA'!H:H,'HORA HORA'!B:B,PF!B37,'HORA HORA'!C:C,PF!$S$1) -> 0 | G37: =SUMIFS('HORA HORA'!J:J,'HORA HORA'!C:C,PF!$G$2,'HORA HORA'!B:B,B37,'HORA HORA'!C:C,PF!$G$2) -> 0 | H37: =SUMIFS('HORA HORA'!K:K,'HORA HORA'!C:C,PF!$G$2,'HORA HORA'!B:B,B37,'HORA HORA'!C:C,PF!$G$2) -> 0 | I37: =SUMIFS('HORA HORA'!L:L,'HORA HORA'!C:C,PF!$G$2,'HORA HORA'!B:B,B37,'HORA HORA'!C:C,PF!$G$2) -> 0 | J37: =COUNTIFS(ACOMPANHAMENTO!S:S,"ACORDO IMPLANTADO",ACOMPANHAMENTO!BC:BC,B37,ACOMPANHAMENTO!H:H,PF!$G$2) -> 0 | K37: =SUMIFS(ACOMPANHAMENTO!O:O,ACOMPANHAMENTO!H:H,PF!$G$2,ACOMPANHAMENTO!BC:BC,B37) -> 0 | L37: =IFERROR(K37/I37,0) -> 0 | M37: =SUMIFS(ACOMPANHAMENTO!R:R,ACOMPANHAMENTO!H:H,PF!$G$2,ACOMPANHAMENTO!BC:BC,PF!B37) -> 0 | N37: =IFERROR(M37/I37,0) -> 0 | O37: =IFERROR(IF(I37/G37=0,"-",I37/G37),"-") -> - | P37: =IFERROR(SUMIFS('HORA HORA'!$K:$K,'HORA HORA'!$B:$B,$B37,'HORA HORA'!$C:$C,"="&"PF")/SUMIFS('HORA HORA'!$J:$J,'HORA HORA'!$B:$B,PF!$B37,'HORA HORA'!$C:$C,$G$2),0) -> 0 | Q37: =IFERROR(IF(J37/I37=0,"-",J37/I37),"-") -> -

Sheet PJ_B1
R1: PJ
I2: Business Banking 1 | R2: B1
A6: 0.27222222 | B6: DIA | C6: CAPACITY | D6: TEMPO DISP | E6: DISCAGEM | F6: ATENDIDA | G6: CPC | H6: CPCA | I6: PROPOSTA | J6: PAGAMENTO | K6: ($) CASH | L6: ($) TKT CASH | M6: ($) CONTABIL | N6: ($) TKT CONTABIL | O6: (%) CONVERSÃO | P6: =AUX!B11 -> (%) CPC | Q6: (%) EFETIVIDADE
A7: 0.27222222 | C7: 10 | D7: =A7*7 -> 1.9055556 | E7: 55737 | F7: 1165 | G7: =AUX!C15 -> 70 | H7: =AUX!C16 -> 46 | I7: =AUX!C17 -> 12 | J7: =AUX!C18 -> 5 | K7: =AUX!C19 -> 75686.94 | L7: =AUX!C20 -> 6307.245 | M7: =AUX!C21 -> 976768.68 | N7: =AUX!C22 -> 81397.39 | O7: =AUX!C35 -> 0.43 | P7: =AUX!C36 -> 0.58 | Q7: =AUX!C37 -> 0.46
A9: 8 | B9: META GERAL | C9: 13 | D9: =D7*A9 -> 15.244444 | E9: =E7*A9 -> 445896 | F9: =F7*A9 -> 9320 | G9: =G7*A9 -> 560 | H9: =H7*A9 -> 368 | I9: =I7*A9 -> 96 | J9: =J7*A9 -> 40 | K9: 1245000 | L9: =L7 -> 6307.245 | M9: 10200000 | N9: =N7 -> 81397.39 | O9: =O7 -> 0.43 | P9: =P7 -> 0.58 | Q9: =Q7 -> 0.46
B10: REALIZADO | C10: =AVERAGE(C17:C23) -> 5.2065268 | D10: =SUM(D17:D37) -> 9.921326 | E10: =SUM(E17:E37) -> 494185 | F10: =SUM(F17:F37) -> 8528 | G10: =SUM(G17:G37) -> 414 | H10: =SUM(H17:H32) -> 245 | I10: =SUM(I17:I32) -> 61 | J10: =SUM(J17:J32) -> 31 | K10: =SUM(K17:K32) -> 565753.49 | L10: =IFERROR(K10/J10,0) -> 18250.113 | M10: =SUM(M17:M28) -> 1772364.6 | N10: =IFERROR(M10/J10,0) -> 57173.05 | O10: =AVERAGE(O17:O37) -> 0.14719954 | P10: =AVERAGE(P17:P24) -> 0.59106594 | Q10: =AVERAGE(Q17:Q37) -> 0.70699405
B11: META RELOGIO | C11: - | D11: =D7*(COUNTIFS(D17:D33,">="&0)) -> 32.394444 | E11: =E7*(COUNTIFS(E17:E33,">="&1)) -> 445896 | F11: =F7*(COUNTIFS(F17:F33,">="&1)) -> 9320 | G11: =G7*(COUNTIFS(G16:G33,">="&1)) -> 560 | H11: =H7*(COUNTIFS(H16:H29,">="&1)) -> 368 | I11: =I7*(COUNTIFS(I16:I29,">="&1)) -> 96 | J11: =J7*(COUNTIFS(J16:J29,">="&1)) -> 35 | K11: =K7*(COUNTIFS(K16:K29,">="&1)) -> 529808.58 | L11: =L9 -> 6307.245 | M11: =M7*(COUNTIFS(M16:M29,">="&1)) -> 6837380.8 | N11: =N9 -> 81397.39 | O11: =O9 -> 0.43 | P11: =P9 -> 0.58 | Q11: =Q9 -> 0.46
B13: (%) META REALIZADO | C13: =C10/C9 -> 0.40050206 | D13: =D10/D9 -> 0.65081585 | E13: =E10/E9 -> 1.1082966 | F13: =F10/F9 -> 0.91502146 | G13: =G10/G9 -> 0.73928571 | H13: =H10/H9 -> 0.66576087 | I13: =I10/I9 -> 0.63541667 | J13: =J10/J9 -> 0.775 | ... Q13: =Q10/Q9 -> 1.5369436
B14: (%) META RELOGIO | C14: - | D14: =D10/D11 -> 0.30626628 | E14: =E10/E11 -> 1.1082966 | F14: =F10/F11 -> 0.91502146 | G14: =G10/G11 -> 0.73928571 | H14: =H10/H11 -> 0.66576087 | I14: =I10/I11 -> 0.63541667 | J14: =IFERROR(J10/J11,0) -> 0.88571429 | K14: =IFERROR(K10/K11,0) -> 1.0678451 | L14: =L10/L11 -> 2.8935157 | M14: =IFERROR(M10/M11,0) -> 0.25921689 | N14: =N10/N11 -> 0.70239415 | O14: =O10/O11 -> 0.34232452 | P14: =P10/P11 -> 1.0190792 | Q14: =Q10/Q11 -> 1.5369436
B16: DATA | C16: REALIZADO | D16: TEMPO REALIZADO | E16: DISCAGEM | F16: ATENDIDA | G16: CPC | H16: CPCA | I16: PROPOSTA | J16: PAGAMENTO | K16: ($) CASH | L16: ($) TKT CASH | M16: ($) CONTABIL | N16: ($) TKT CONTABIL | O16: (%) CONVERSÃO | P16: (%) CPC | Q16: (%) EFETIVIDADE
B17: 46266 | C17: =D17/$A$7 -> 6.3419327 | D17: =SUMIFS(TEMPOS!AL:AL,TEMPOS!X:X,$R$2,TEMPOS!Y:Y,B17) -> 1.726415 | E17: =SUMIFS('HORA HORA'!G:G,'HORA HORA'!C:C,PJ_B1!$R$1,'HORA HORA'!B:B,PJ_B1!B17,'HORA HORA'!Y:Y,"<>"&"EMPRESAS_2") -> 48484 | F17: =SUMIFS('HORA HORA'!H:H,'HORA HORA'!C:C,PJ_B1!$R$1,'HORA HORA'!B:B,PJ_B1!B17,'HORA HORA'!Y:Y,"<>"&"EMPRESAS_2") -> 1186 | G17: =SUMIFS('HORA HORA'!J:J,'HORA HORA'!C:C,PJ_B1!$R$1,'HORA HORA'!B:B,PJ_B1!B17,'HORA HORA'!Y:Y,"<>"&"EMPRESAS_2") -> 72 | H17: =SUMIFS('HORA HORA'!K:K,'HORA HORA'!C:C,PJ_B1!$R$1,'HORA HORA'!B:B,PJ_B1!B17,'HORA HORA'!Y:Y,"<>"&"EMPRESAS_2") -> 45 | I17: =SUMIFS('HORA HORA'!L:L,'HORA HORA'!C:C,PJ_B1!$R$1,'HORA HORA'!B:B,PJ_B1!B17,'HORA HORA'!Y:Y,"<>"&"EMPRESAS_2") -> 10 | J17: =COUNTIFS(ACOMPANHAMENTO!S:S,"ACORDO IMPLANTADO",ACOMPANHAMENTO!BC:BC,B17,ACOMPANHAMENTO!H:H,PJ_B1!$R$1,ACOMPANHAMENTO!I:I,"="&"Business Banking 1") -> 2 | K17: =SUMIFS(ACOMPANHAMENTO!O:O,ACOMPANHAMENTO!H:H,PJ_B1!$R$1,ACOMPANHAMENTO!BC:BC,PJ_B1!B17,ACOMPANHAMENTO!I:I,"="&"Business Banking 1") -> 72000 | L17: =K17/I17 -> 7200 | M17: =SUMIFS(ACOMPANHAMENTO!R:R,ACOMPANHAMENTO!H:H,PJ_B1!$R$1,ACOMPANHAMENTO!BC:BC,PJ_B1!B17,ACOMPANHAMENTO!I:I,"="&"Business Banking 1") -> 41195.64 | N17: =M17/I17 -> 4119.564 | O17: =IFERROR(IF(I17/G17=0,"-",I17/G17),"-") -> 0.13888889 | P17: =SUMIFS('HORA HORA'!$K:$K,'HORA HORA'!$B:$B,PJ_B1!$B17,'HORA HORA'!$C:$C,"="&"PJ",'HORA HORA'!$Y:$Y,"<>"&"EMPRESAS_2")/SUMIFS('HORA HORA'!$J:$J,'HORA HORA'!$B:$B,PJ_B1!$B17,'HORA HORA'!$C:$C,"="&"PJ",'HORA HORA'!$Y:$Y,"<>"&"EMPRESAS_2") -> 0.625 | Q17: =IFERROR(J17/I17,"-") -> 0.2
B18: 46267 | C18: =D18/$A$7 -> 5.9954069 | D18: =SUMIFS(TEMPOS!AL:AL,TEMPOS!X:X,$R$2,TEMPOS!Y:Y,B18) -> 1.632083 | E18: =SUMIFS('HORA HORA'!G:G,'HORA HORA'!C:C,PJ_B1!$R$1,'HORA HORA'!B:B,PJ_B1!B18,'HORA HORA'!Y:Y,"<>"&"EMPRESAS_2") -> 48063 | F18: =SUMIFS('HORA HORA'!H:H,'HORA HORA'!C:C,PJ_B1!$R$1,'HORA HORA'!B:B,PJ_B1!B18,'HORA HORA'!Y:Y,"<>"&"EMPRESAS_2") -> 1206 | G18: =SUMIFS('HORA HORA'!J:J,'HORA HORA'!C:C,PJ_B1!$R$1,'HORA HORA'!B:B,PJ_B1!B18,'HORA HORA'!Y:Y,"<>"&"EMPRESAS_2") -> 42 | H18: =SUMIFS('HORA HORA'!K:K,'HORA HORA'!C:C,PJ_B1!$R$1,'HORA HORA'!B:B,PJ_B1!B18,'HORA HORA'!Y:Y,"<>"&"EMPRESAS_2") -> 27 | I18: =SUMIFS('HORA HORA'!L:L,'HORA HORA'!C:C,PJ_B1!$R$1,'HORA HORA'!B:B,PJ_B1!B18,'HORA HORA'!Y:Y,"<>"&"EMPRESAS_2") -> 6 | J18: =COUNTIFS(ACOMPANHAMENTO!S:S,"ACORDO IMPLANTADO",ACOMPANHAMENTO!BC:BC,B18,ACOMPANHAMENTO!H:H,PJ_B1!$R$1,ACOMPANHAMENTO!I:I,"="&"Business Banking 1") -> 4 | K18: =SUMIFS(ACOMPANHAMENTO!O:O,ACOMPANHAMENTO!H:H,PJ_B1!$R$1,ACOMPANHAMENTO!BC:BC,PJ_B1!B18,ACOMPANHAMENTO!I:I,"="&"Business Banking 1") -> 37078.58 | L18: =IFERROR(K18/I18,0) -> 6179.7633 | M18: =SUMIFS(ACOMPANHAMENTO!R:R,ACOMPANHAMENTO!H:H,PJ_B1!$R$1,ACOMPANHAMENTO!BC:BC,PJ_B1!B18,ACOMPANHAMENTO!I:I,"="&"Business Banking 1") -> 227832.3 | N18: =IFERROR(M18/I18,0) -> 37972.05 | O18: =IFERROR(IF(I18/G18=0,"-",I18/G18),"-") -> 0.14285714 | P18: =IFERROR(SUMIFS('HORA HORA'!$K:$K,'HORA HORA'!$B:$B,PJ_B1!$B18,'HORA HORA'!$C:$C,"="&"PJ",'HORA HORA'!$Y:$Y,"<>"&"EMPRESAS_2")/SUMIFS('HORA HORA'!$J:$J,'HORA HORA'!$B:$B,PJ_B1!$B18,'HORA HORA'!$C:$C,"="&"PJ",'HORA HORA'!$Y:$Y,"<>"&"EMPRESAS_2"),0) -> 0.64285714 | Q18: =IFERROR(J18/I18,"-") -> 0.66666667
B19: 46268 | C19: =D19/$A$7 -> 4.6156922 | D19: =SUMIFS(TEMPOS!AL:AL,TEMPOS!X:X,$R$2,TEMPOS!Y:Y,B19) -> 1.256494 | E19: =SUMIFS('HORA HORA'!G:G,'HORA HORA'!C:C,PJ_B1!$R$1,'HORA HORA'!B:B,PJ_B1!B19,'HORA HORA'!Y:Y,"<>"&"EMPRESAS_2") -> 34619 | F19: =SUMIFS('HORA HORA'!H:H,'HORA HORA'!C:C,PJ_B1!$R$1,'HORA HORA'!B:B,PJ_B1!B19,'HORA HORA'!Y:Y,"<>"&"EMPRESAS_2") -> 687 | G19: =SUMIFS('HORA HORA'!J:J,'HORA HORA'!C:C,PJ_B1!$R$1,'HORA HORA'!B:B,PJ_B1!B19,'HORA HORA'!Y:Y,"<>"&"EMPRESAS_2") -> 49 | H19: =SUMIFS('HORA HORA'!K:K,'HORA HORA'!C:C,PJ_B1!$R$1,'HORA HORA'!B:B,PJ_B1!B19,'HORA HORA'!Y:Y,"<>"&"EMPRESAS_2") -> 28 | I19: =SUMIFS('HORA HORA'!L:L,'HORA HORA'!C:C,PJ_B1!$R$1,'HORA HORA'!B:B,PJ_B1!B19,'HORA HORA'!Y:Y,"<>"&"EMPRESAS_2") -> 12 | J19: =COUNTIFS(ACOMPANHAMENTO!S:S,"ACORDO IMPLANTADO",ACOMPANHAMENTO!BC:BC,B19,ACOMPANHAMENTO!H:H,PJ_B1!$R$1,ACOMPANHAMENTO!I:I,"="&"Business Banking 1") -> 0 | K19: =SUMIFS(ACOMPANHAMENTO!O:O,ACOMPANHAMENTO!H:H,PJ_B1!$R$1,ACOMPANHAMENTO!BC:BC,PJ_B1!B19,ACOMPANHAMENTO!I:I,"="&"Business Banking 1") -> 0 | L19: =IFERROR(K19/I19,0) -> 0 | M19: =SUMIFS(ACOMPANHAMENTO!R:R,ACOMPANHAMENTO!H:H,PJ_B1!$R$1,ACOMPANHAMENTO!BC:BC,PJ_B1!B19,ACOMPANHAMENTO!I:I,"="&"Business Banking 1") -> 0 | N19: =IFERROR(M19/I19,0) -> 0 | O19: =IFERROR(IF(I19/G19=0,"-",I19/G19),"-") -> 0.24489796 | P19: =IFERROR(SUMIFS('HORA HORA'!$K:$K,'HORA HORA'!$B:$B,PJ_B1!$B19,'HORA HORA'!$C:$C,"="&"PJ",'HORA HORA'!$Y:$Y,"<>"&"EMPRESAS_2")/SUMIFS('HORA HORA'!$J:$J,'HORA HORA'!$B:$B,PJ_B1!$B19,'HORA HORA'!$C:$C,"="&"PJ",'HORA HORA'!$Y:$Y,"<>"&"EMPRESAS_2"),0) -> 0.57142857 | Q19: =IFERROR(J19/I19,"-") -> 0
B20: 46269 | C20: =D20/$A$7 -> 3.6886922 | D20: =SUMIFS(TEMPOS!AL:AL,TEMPOS!X:X,$R$2,TEMPOS!Y:Y,B20) -> 1.004144 | E20: =SUMIFS('HORA HORA'!G:G,'HORA HORA'!C:C,PJ_B1!$R$1,'HORA HORA'!B:B,PJ_B1!B20,'HORA HORA'!Y:Y,"<>"&"EMPRESAS_2") -> 32943 | F20: =SUMIFS('HORA HORA'!H:H,'HORA HORA'!C:C,PJ_B1!$R$1,'HORA HORA'!B:B,PJ_B1!B20,'HORA HORA'!Y:Y,"<>"&"EMPRESAS_2") -> 595 | G20: =SUMIFS('HORA HORA'!J:J,'HORA HORA'!C:C,PJ_B1!$R$1,'HORA HORA'!B:B,PJ_B1!B20,'HORA HORA'!Y:Y,"<>"&"EMPRESAS_2") -> 24 | H20: =SUMIFS('HORA HORA'!K:K,'HORA HORA'!C:C,PJ_B1!$R$1,'HORA HORA'!B:B,PJ_B1!B20,'HORA HORA'!Y:Y,"<>"&"EMPRESAS_2") -> 14 | I20: =SUMIFS('HORA HORA'!L:L,'HORA HORA'!C:C,PJ_B1!$R$1,'HORA HORA'!B:B,PJ_B1!B20,'HORA HORA'!Y:Y,"<>"&"EMPRESAS_2") -> 3 | J20: =COUNTIFS(ACOMPANHAMENTO!S:S,"ACORDO IMPLANTADO",ACOMPANHAMENTO!BC:BC,B20,ACOMPANHAMENTO!H:H,PJ_B1!$R$1,ACOMPANHAMENTO!I:I,"="&"Business Banking 1") -> 6 | K20: =SUMIFS(ACOMPANHAMENTO!O:O,ACOMPANHAMENTO!H:H,PJ_B1!$R$1,ACOMPANHAMENTO!BC:BC,PJ_B1!B20,ACOMPANHAMENTO!I:I,"="&"Business Banking 1") -> 82441.3 | L20: =IFERROR(K20/I20,0) -> 27480.433 | M20: =SUMIFS(ACOMPANHAMENTO!R:R,ACOMPANHAMENTO!H:H,PJ_B1!$R$1,ACOMPANHAMENTO!BC:BC,PJ_B1!B20,ACOMPANHAMENTO!I:I,"="&"Business Banking 1") -> 95773.78 | N20: =IFERROR(M20/I20,0) -> 31924.593 | O20: =IFERROR(IF(I20/G20=0,"-",I20/G20),"-") -> 0.125 | P20: =IFERROR(SUMIFS('HORA HORA'!$K:$K,'HORA HORA'!$B:$B,PJ_B1!$B20,'HORA HORA'!$C:$C,"="&"PJ",'HORA HORA'!$Y:$Y,"<>"&"EMPRESAS_2")/SUMIFS('HORA HORA'!$J:$J,'HORA HORA'!$B:$B,PJ_B1!$B20,'HORA HORA'!$C:$C,"="&"PJ",'HORA HORA'!$Y:$Y,"<>"&"EMPRESAS_2"),0) -> 0.58333333 | Q20: =IFERROR(J20/I20,"-") -> 2
B21: 46273 | C21: =D21/$A$7 -> 4.9910731 | D21: =SUMIFS(TEMPOS!AL:AL,TEMPOS!X:X,$R$2,TEMPOS!Y:Y,B21) -> 1.358681 | E21: =SUMIFS('HORA HORA'!G:G,'HORA HORA'!C:C,PJ_B1!$R$1,'HORA HORA'!B:B,PJ_B1!B21,'HORA HORA'!Y:Y,"<>"&"EMPRESAS_2") -> 49897 | F21: =SUMIFS('HORA HORA'!H:H,'HORA HORA'!C:C,PJ_B1!$R$1,'HORA HORA'!B:B,PJ_B1!B21,'HORA HORA'!Y:Y,"<>"&"EMPRESAS_2") -> 913 | G21: =SUMIFS('HORA HORA'!J:J,'HORA HORA'!C:C,PJ_B1!$R$1,'HORA HORA'!B:B,PJ_B1!B21,'HORA HORA'!Y:Y,"<>"&"EMPRESAS_2") -> 53 | H21: =SUMIFS('HORA HORA'!K:K,'HORA HORA'!C:C,PJ_B1!$R$1,'HORA HORA'!B:B,PJ_B1!B21,'HORA HORA'!Y:Y,"<>"&"EMPRESAS_2") -> 28 | I21: =SUMIFS('HORA HORA'!L:L,'HORA HORA'!C:C,PJ_B1!$R$1,'HORA HORA'!B:B,PJ_B1!B21,'HORA HORA'!Y:Y,"<>"&"EMPRESAS_2") -> 5 | J21: =COUNTIFS(ACOMPANHAMENTO!S:S,"ACORDO IMPLANTADO",ACOMPANHAMENTO!BC:BC,B21,ACOMPANHAMENTO!H:H,PJ_B1!$R$1,ACOMPANHAMENTO!I:I,"="&"Business Banking 1") -> 6 | K21: =SUMIFS(ACOMPANHAMENTO!O:O,ACOMPANHAMENTO!H:H,PJ_B1!$R$1,ACOMPANHAMENTO!BC:BC,PJ_B1!B21,ACOMPANHAMENTO!I:I,"="&"Business Banking 1") -> 34385.19 | L21: =IFERROR(K21/I21,0) -> 6877.038 | M21: =SUMIFS(ACOMPANHAMENTO!R:R,ACOMPANHAMENTO!H:H,PJ_B1!$R$1,ACOMPANHAMENTO!BC:BC,PJ_B1!B21,ACOMPANHAMENTO!I:I,"="&"Business Banking 1") -> 662287.64 | N21: =IFERROR(M21/I21,0) -> 132457.53 | O21: =IFERROR(IF(I21/G21=0,"-",I21/G21),"-") -> 0.094339623 | P21: =IFERROR(SUMIFS('HORA HORA'!$K:$K,'HORA HORA'!$B:$B,PJ_B1!$B21,'HORA HORA'!$C:$C,"="&"PJ",'HORA HORA'!$Y:$Y,"<>"&"EMPRESAS_2")/SUMIFS('HORA HORA'!$J:$J,'HORA HORA'!$B:$B,PJ_B1!$B21,'HORA HORA'!$C:$C,"="&"PJ",'HORA HORA'!$Y:$Y,"<>"&"EMPRESAS_2"),0) -> 0.52830189 | Q21: =IFERROR(J21/I21,"-") -> 1.2
B22: 46274 | C22: =D22/$A$7 -> 4.9892878 | D22: =SUMIFS(TEMPOS!AL:AL,TEMPOS!X:X,$R$2,TEMPOS!Y:Y,B22) -> 1.358195 | E22: =SUMIFS('HORA HORA'!G:G,'HORA HORA'!C:C,PJ_B1!$R$1,'HORA HORA'!B:B,PJ_B1!B22,'HORA HORA'!Y:Y,"<>"&"EMPRESAS_2") -> 78395 | F22: =SUMIFS('HORA HORA'!H:H,'HORA HORA'!C:C,PJ_B1!$R$1,'HORA HORA'!B:B,PJ_B1!B22,'HORA HORA'!Y:Y,"<>"&"EMPRESAS_2") -> 1486 | G22: =SUMIFS('HORA HORA'!J:J,'HORA HORA'!C:C,PJ_B1!$R$1,'HORA HORA'!B:B,PJ_B1!B22,'HORA HORA'!Y:Y,"<>"&"EMPRESAS_2") -> 59 | H22: =SUMIFS('HORA HORA'!K:K,'HORA HORA'!C:C,PJ_B1!$R$1,'HORA HORA'!B:B,PJ_B1!B22,'HORA HORA'!Y:Y,"<>"&"EMPRESAS_2") -> 28 | I22: =SUMIFS('HORA HORA'!L:L,'HORA HORA'!C:C,PJ_B1!$R$1,'HORA HORA'!B:B,PJ_B1!B22,'HORA HORA'!Y:Y,"<>"&"EMPRESAS_2") -> 10 | J22: =COUNTIFS(ACOMPANHAMENTO!S:S,"ACORDO IMPLANTADO",ACOMPANHAMENTO!BC:BC,B22,ACOMPANHAMENTO!H:H,PJ_B1!$R$1,ACOMPANHAMENTO!I:I,"="&"Business Banking 1") -> 5 | K22: =SUMIFS(ACOMPANHAMENTO!O:O,ACOMPANHAMENTO!H:H,PJ_B1!$R$1,ACOMPANHAMENTO!BC:BC,PJ_B1!B22,ACOMPANHAMENTO!I:I,"="&"Business Banking 1") -> 221827.5 | L22: =IFERROR(K22/I22,0) -> 22182.75 | M22: =SUMIFS(ACOMPANHAMENTO!R:R,ACOMPANHAMENTO!H:H,PJ_B1!$R$1,ACOMPANHAMENTO!BC:BC,PJ_B1!B22,ACOMPANHAMENTO!I:I,"="&"Business Banking 1") -> 304928.99 | N22: =IFERROR(M22/I22,0) -> 30492.899 | O22: =IFERROR(IF(I22/G22=0,"-",I22/G22),"-") -> 0.16949153 | P22: =IFERROR(SUMIFS('HORA HORA'!$K:$K,'HORA HORA'!$B:$B,PJ_B1!$B22,'HORA HORA'!$C:$C,"="&"PJ",'HORA HORA'!$Y:$Y,"<>"&"EMPRESAS_2")/SUMIFS('HORA HORA'!$J:$J,'HORA HORA'!$B:$B,PJ_B1!$B22,'HORA HORA'!$C:$C,"="&"PJ",'HORA HORA'!$Y:$Y,"<>"&"EMPRESAS_2"),0) -> 0.47457627 | Q22: =IFERROR(J22/I22,"-") -> 0.5
B23: 46275 | C23: =D23/$A$7 -> 5.8236024 | D23: =SUMIFS(TEMPOS!AL:AL,TEMPOS!X:X,$R$2,TEMPOS!Y:Y,B23) -> 1.585314 | E23: =SUMIFS('HORA HORA'!G:G,'HORA HORA'!C:C,PJ_B1!$R$1,'HORA HORA'!B:B,PJ_B1!B23,'HORA HORA'!Y:Y,"<>"&"EMPRESAS_2") -> 94812 | F23: =SUMIFS('HORA HORA'!H:H,'HORA HORA'!C:C,PJ_B1!$R$1,'HORA HORA'!B:B,PJ_B1!B23,'HORA HORA'!Y:Y,"<>"&"EMPRESAS_2") -> 1171 | G23: =SUMIFS('HORA HORA'!J:J,'HORA HORA'!C:C,PJ_B1!$R$1,'HORA HORA'!B:B,PJ_B1!B23,'HORA HORA'!Y:Y,"<>"&"EMPRESAS_2") -> 60 | H23: =SUMIFS('HORA HORA'!K:K,'HORA HORA'!C:C,PJ_B1!$R$1,'HORA HORA'!B:B,PJ_B1!B23,'HORA HORA'!Y:Y,"<>"&"EMPRESAS_2") -> 40 | I23: =SUMIFS('HORA HORA'!L:L,'HORA HORA'!C:C,PJ_B1!$R$1,'HORA HORA'!B:B,PJ_B1!B23,'HORA HORA'!Y:Y,"<>"&"EMPRESAS_2") -> 7 | J23: =COUNTIFS(ACOMPANHAMENTO!S:S,"ACORDO IMPLANTADO",ACOMPANHAMENTO!BC:BC,B23,ACOMPANHAMENTO!H:H,PJ_B1!$R$1,ACOMPANHAMENTO!I:I,"="&"Business Banking 1") -> 5 | K23: =SUMIFS(ACOMPANHAMENTO!O:O,ACOMPANHAMENTO!H:H,PJ_B1!$R$1,ACOMPANHAMENTO!BC:BC,PJ_B1!B23,ACOMPANHAMENTO!I:I,"="&"Business Banking 1") -> 34020.92 | L23: =IFERROR(K23/I23,0) -> 4860.1314 | M23: =SUMIFS(ACOMPANHAMENTO!R:R,ACOMPANHAMENTO!H:H,PJ_B1!$R$1,ACOMPANHAMENTO!BC:BC,PJ_B1!B23,ACOMPANHAMENTO!I:I,"="&"Business Banking 1") -> 397651 | N23: =IFERROR(M23/I23,0) -> 56807.286 | O23: =IFERROR(IF(I23/G23=0,"-",I23/G23),"-") -> 0.11666667 | P23: =IFERROR(SUMIFS('HORA HORA'!$K:$K,'HORA HORA'!$B:$B,PJ_B1!$B23,'HORA HORA'!$C:$C,"="&"PJ",'HORA HORA'!$Y:$Y,"<>"&"EMPRESAS_2")/SUMIFS('HORA HORA'!$J:$J,'HORA HORA'!$B:$B,PJ_B1!$B23,'HORA HORA'!$C:$C,"="&"PJ",'HORA HORA'!$Y:$Y,"<>"&"EMPRESAS_2"),0) -> 0.66666667 | Q23: =IFERROR(J23/I23,"-") -> 0.71428571
B24: 46276 | C24: =D24/$A$7 -> 0 | D24: =SUMIFS(TEMPOS!AL:AL,TEMPOS!X:X,$R$2,TEMPOS!Y:Y,B24) -> 0 | E24: =SUMIFS('HORA HORA'!G:G,'HORA HORA'!C:C,PJ_B1!$R$1,'HORA HORA'!B:B,PJ_B1!B24,'HORA HORA'!Y:Y,"<>"&"EMPRESAS_2") -> 106972 | F24: =SUMIFS('HORA HORA'!H:H,'HORA HORA'!C:C,PJ_B1!$R$1,'HORA HORA'!B:B,PJ_B1!B24,'HORA HORA'!Y:Y,"<>"&"EMPRESAS_2") -> 1284 | G24: =SUMIFS('HORA HORA'!J:J,'HORA HORA'!C:C,PJ_B1!$R$1,'HORA HORA'!B:B,PJ_B1!B24,'HORA HORA'!Y:Y,"<>"&"EMPRESAS_2") -> 55 | H24: =SUMIFS('HORA HORA'!K:K,'HORA HORA'!C:C,PJ_B1!$R$1,'HORA HORA'!B:B,PJ_B1!B24,'HORA HORA'!Y:Y,"<>"&"EMPRESAS_2") -> 35 | I24: =SUMIFS('HORA HORA'!L:L,'HORA HORA'!C:C,PJ_B1!$R$1,'HORA HORA'!B:B,PJ_B1!B24,'HORA HORA'!Y:Y,"<>"&"EMPRESAS_2") -> 8 | J24: =COUNTIFS(ACOMPANHAMENTO!S:S,"ACORDO IMPLANTADO",ACOMPANHAMENTO!BC:BC,B24,ACOMPANHAMENTO!H:H,PJ_B1!$R$1,ACOMPANHAMENTO!I:I,"="&"Business Banking 1") -> 3 | K24: =SUMIFS(ACOMPANHAMENTO!O:O,ACOMPANHAMENTO!H:H,PJ_B1!$R$1,ACOMPANHAMENTO!BC:BC,PJ_B1!B24,ACOMPANHAMENTO!I:I,"="&"Business Banking 1") -> 84000 | L24: =IFERROR(K24/I24,0) -> 10500 | M24: =SUMIFS(ACOMPANHAMENTO!R:R,ACOMPANHAMENTO!H:H,PJ_B1!$R$1,ACOMPANHAMENTO!BC:BC,PJ_B1!B24,ACOMPANHAMENTO!I:I,"="&"Business Banking 1") -> 42695.21 | N24: =IFERROR(M24/I24,0) -> 5336.9012 | O24: =IFERROR(IF(I24/G24=0,"-",I24/G24),"-") -> 0.14545455 | P24: =IFERROR(SUMIFS('HORA HORA'!$K:$K,'HORA HORA'!$B:$B,PJ_B1!$B24,'HORA HORA'!$C:$C,"="&"PJ",'HORA HORA'!$Y:$Y,"<>"&"EMPRESAS_2")/SUMIFS('HORA HORA'!$J:$J,'HORA HORA'!$B:$B,PJ_B1!$B24,'HORA HORA'!$C:$C,"="&"PJ",'HORA HORA'!$Y:$Y,"<>"&"EMPRESAS_2"),0) -> 0.63636364 | Q24: =IFERROR(J24/I24,"-") -> 0.375
B25: 46279 | C25: =D25/$A$7 -> 0 | D25: =SUMIFS(TEMPOS!AL:AL,TEMPOS!X:X,$R$2,TEMPOS!Y:Y,B25) -> 0 | E25: =SUMIFS('HORA HORA'!G:G,'HORA HORA'!C:C,PJ_B1!$R$1,'HORA HORA'!B:B,PJ_B1!B25,'HORA HORA'!Y:Y,"<>"&"EMPRESAS_2") -> 0 | F25: =SUMIFS('HORA HORA'!H:H,'HORA HORA'!C:C,PJ_B1!$R$1,'HORA HORA'!B:B,PJ_B1!B25,'HORA HORA'!Y:Y,"<>"&"EMPRESAS_2") -> 0 | G25: =SUMIFS('HORA HORA'!J:J,'HORA HORA'!C:C,PJ_B1!$R$1,'HORA HORA'!B:B,PJ_B1!B25,'HORA HORA'!Y:Y,"<>"&"EMPRESAS_2") -> 0 | H25: =SUMIFS('HORA HORA'!K:K,'HORA HORA'!C:C,PJ_B1!$R$1,'HORA HORA'!B:B,PJ_B1!B25,'HORA HORA'!Y:Y,"<>"&"EMPRESAS_2") -> 0 | I25: =SUMIFS('HORA HORA'!L:L,'HORA HORA'!C:C,PJ_B1!$R$1,'HORA HORA'!B:B,PJ_B1!B25,'HORA HORA'!Y:Y,"<>"&"EMPRESAS_2") -> 0 | J25: =COUNTIFS(ACOMPANHAMENTO!S:S,"ACORDO IMPLANTADO",ACOMPANHAMENTO!BC:BC,B25,ACOMPANHAMENTO!H:H,PJ_B1!$R$1,ACOMPANHAMENTO!I:I,"="&"Business Banking 1") -> 0 | K25: =SUMIFS(ACOMPANHAMENTO!O:O,ACOMPANHAMENTO!H:H,PJ_B1!$R$1,ACOMPANHAMENTO!BC:BC,PJ_B1!B25,ACOMPANHAMENTO!I:I,"="&"Business Banking 1") -> 0 | L25: =IFERROR(K25/I25,0) -> 0 | M25: =SUMIFS(ACOMPANHAMENTO!R:R,ACOMPANHAMENTO!H:H,PJ_B1!$R$1,ACOMPANHAMENTO!BC:BC,PJ_B1!B25,ACOMPANHAMENTO!I:I,"="&"Business Banking 1") -> 0 | N25: =IFERROR(M25/I25,0) -> 0 | O25: =IFERROR(IF(I25/G25=0,"-",I25/G25),"-") -> - | P25: =IFERROR(SUMIFS('HORA HORA'!$K:$K,'HORA HORA'!$B:$B,PJ_B1!$B25,'HORA HORA'!$C:$C,"="&"PJ",'HORA HORA'!$Y:$Y,"<>"&"EMPRESAS_2")/SUMIFS('HORA HORA'!$J:$J,'HORA HORA'!$B:$B,PJ_B1!$B25,'HORA HORA'!$C:$C,"="&"PJ",'HORA HORA'!$Y:$Y,"<>"&"EMPRESAS_2"),0) -> 0 | Q25: =IFERROR(J25/I25,"-") -> -
B26: 46280 | C26: =D26/$A$7 -> 0 | D26: =SUMIFS(TEMPOS!AL:AL,TEMPOS!X:X,$R$2,TEMPOS!Y:Y,B26) -> 0 | E26: =SUMIFS('HORA HORA'!G:G,'HORA HORA'!C:C,PJ_B1!$R$1,'HORA HORA'!B:B,PJ_B1!B26,'HORA HORA'!Y:Y,"<>"&"EMPRESAS_2") -> 0 | F26: =SUMIFS('HORA HORA'!H:H,'HORA HORA'!C:C,PJ_B1!$R$1,'HORA HORA'!B:B,PJ_B1!B26,'HORA HORA'!Y:Y,"<>"&"EMPRESAS_2") -> 0 | G26: =SUMIFS('HORA HORA'!J:J,'HORA HORA'!C:C,PJ_B1!$R$1,'HORA HORA'!B:B,PJ_B1!B26,'HORA HORA'!Y:Y,"<>"&"EMPRESAS_2") -> 0 | H26: =SUMIFS('HORA HORA'!K:K,'HORA HORA'!C:C,PJ_B1!$R$1,'HORA HORA'!B:B,PJ_B1!B26,'HORA HORA'!Y:Y,"<>"&"EMPRESAS_2") -> 0 | I26: =SUMIFS('HORA HORA'!L:L,'HORA HORA'!C:C,PJ_B1!$R$1,'HORA HORA'!B:B,PJ_B1!B26,'HORA HORA'!Y:Y,"<>"&"EMPRESAS_2") -> 0 | J26: =COUNTIFS(ACOMPANHAMENTO!S:S,"ACORDO IMPLANTADO",ACOMPANHAMENTO!BC:BC,B26,ACOMPANHAMENTO!H:H,PJ_B1!$R$1,ACOMPANHAMENTO!I:I,"="&"Business Banking 1") -> 0 | K26: =SUMIFS(ACOMPANHAMENTO!O:O,ACOMPANHAMENTO!H:H,PJ_B1!$R$1,ACOMPANHAMENTO!BC:BC,PJ_B1!B26,ACOMPANHAMENTO!I:I,"="&"Business Banking 1") -> 0 | L26: =IFERROR(K26/I26,0) -> 0 | M26: =SUMIFS(ACOMPANHAMENTO!R:R,ACOMPANHAMENTO!H:H,PJ_B1!$R$1,ACOMPANHAMENTO!BC:BC,PJ_B1!B26,ACOMPANHAMENTO!I:I,"="&"Business Banking 1") -> 0 | N26: =IFERROR(M26/I26,0) -> 0 | O26: =IFERROR(IF(I26/G26=0,"-",I26/G26),"-") -> - | P26: =IFERROR(SUMIFS('HORA HORA'!$K:$K,'HORA HORA'!$B:$B,PJ_B1!$B26,'HORA HORA'!$C:$C,"="&"PJ",'HORA HORA'!$Y:$Y,"<>"&"EMPRESAS_2")/SUMIFS('HORA HORA'!$J:$J,'HORA HORA'!$B:$B,PJ_B1!$B26,'HORA HORA'!$C:$C,"="&"PJ",'HORA HORA'!$Y:$Y,"<>"&"EMPRESAS_2"),0) -> 0 | Q26: =IFERROR(J26/I26,"-") -> -
B27: 46281 | C27: =D27/$A$7 -> 0 | D27: =SUMIFS(TEMPOS!AL:AL,TEMPOS!X:X,$R$2,TEMPOS!Y:Y,B27) -> 0 | E27: =SUMIFS('HORA HORA'!G:G,'HORA HORA'!C:C,PJ_B1!$R$1,'HORA HORA'!B:B,PJ_B1!B27,'HORA HORA'!Y:Y,"<>"&"EMPRESAS_2") -> 0 | F27: =SUMIFS('HORA HORA'!H:H,'HORA HORA'!C:C,PJ_B1!$R$1,'HORA HORA'!B:B,PJ_B1!B27,'HORA HORA'!Y:Y,"<>"&"EMPRESAS_2") -> 0 | G27: =SUMIFS('HORA HORA'!J:J,'HORA HORA'!C:C,PJ_B1!$R$1,'HORA HORA'!B:B,PJ_B1!B27,'HORA HORA'!Y:Y,"<>"&"EMPRESAS_2") -> 0 | H27: =SUMIFS('HORA HORA'!K:K,'HORA HORA'!C:C,PJ_B1!$R$1,'HORA HORA'!B:B,PJ_B1!B27,'HORA HORA'!Y:Y,"<>"&"EMPRESAS_2") -> 0 | I27: =SUMIFS('HORA HORA'!L:L,'HORA HORA'!C:C,PJ_B1!$R$1,'HORA HORA'!B:B,PJ_B1!B27,'HORA HORA'!Y:Y,"<>"&"EMPRESAS_2") -> 0 | J27: =COUNTIFS(ACOMPANHAMENTO!S:S,"ACORDO IMPLANTADO",ACOMPANHAMENTO!BC:BC,B27,ACOMPANHAMENTO!H:H,PJ_B1!$R$1,ACOMPANHAMENTO!I:I,"="&"Business Banking 1") -> 0 | K27: =SUMIFS(ACOMPANHAMENTO!O:O,ACOMPANHAMENTO!H:H,PJ_B1!$R$1,ACOMPANHAMENTO!BC:BC,PJ_B1!B27,ACOMPANHAMENTO!I:I,"="&"Business Banking 1") -> 0 | L27: =IFERROR(K27/I27,0) -> 0 | M27: =SUMIFS(ACOMPANHAMENTO!R:R,ACOMPANHAMENTO!H:H,PJ_B1!$R$1,ACOMPANHAMENTO!BC:BC,PJ_B1!B27,ACOMPANHAMENTO!I:I,"="&"Business Banking 1") -> 0 | N27: =IFERROR(M27/I27,0) -> 0 | O27: =IFERROR(IF(I27/G27=0,"-",I27/G27),"-") -> - | P27: =IFERROR(SUMIFS('HORA HORA'!$K:$K,'HORA HORA'!$B:$B,PJ_B1!$B27,'HORA HORA'!$C:$C,"="&"PJ",'HORA HORA'!$Y:$Y,"<>"&"EMPRESAS_2")/SUMIFS('HORA HORA'!$J:$J,'HORA HORA'!$B:$B,PJ_B1!$B27,'HORA HORA'!$C:$C,"="&"PJ",'HORA HORA'!$Y:$Y,"<>"&"EMPRESAS_2"),0) -> 0 | Q27: =IFERROR(J27/I27,"-") -> -
B28: 46282 | C28: =D28/$A$7 -> 0 | D28: =SUMIFS(TEMPOS!AL:AL,TEMPOS!X:X,$R$2,TEMPOS!Y:Y,B28) -> 0 | E28: =SUMIFS('HORA HORA'!G:G,'HORA HORA'!C:C,PJ_B1!$R$1,'HORA HORA'!B:B,PJ_B1!B28,'HORA HORA'!Y:Y,"<>"&"EMPRESAS_2") -> 0 | F28: =SUMIFS('HORA HORA'!H:H,'HORA HORA'!C:C,PJ_B1!$R$1,'HORA HORA'!B:B,PJ_B1!B28,'HORA HORA'!Y:Y,"<>"&"EMPRESAS_2") -> 0 | G28: =SUMIFS('HORA HORA'!J:J,'HORA HORA'!C:C,PJ_B1!$R$1,'HORA HORA'!B:B,PJ_B1!B28,'HORA HORA'!Y:Y,"<>"&"EMPRESAS_2") -> 0 | H28: =SUMIFS('HORA HORA'!K:K,'HORA HORA'!C:C,PJ_B1!$R$1,'HORA HORA'!B:B,PJ_B1!B28,'HORA HORA'!Y:Y,"<>"&"EMPRESAS_2") -> 0 | I28: =SUMIFS('HORA HORA'!L:L,'HORA HORA'!C:C,PJ_B1!$R$1,'HORA HORA'!B:B,PJ_B1!B28,'HORA HORA'!Y:Y,"<>"&"EMPRESAS_2") -> 0 | J28: =COUNTIFS(ACOMPANHAMENTO!S:S,"ACORDO IMPLANTADO",ACOMPANHAMENTO!BC:BC,B28,ACOMPANHAMENTO!H:H,PJ_B1!$R$1,ACOMPANHAMENTO!I:I,"="&"Business Banking 1") -> 0 | K28: =SUMIFS(ACOMPANHAMENTO!O:O,ACOMPANHAMENTO!H:H,PJ_B1!$R$1,ACOMPANHAMENTO!BC:BC,PJ_B1!B28,ACOMPANHAMENTO!I:I,"="&"Business Banking 1") -> 0 | L28: =IFERROR(K28/I28,0) -> 0 | M28: =SUMIFS(ACOMPANHAMENTO!R:R,ACOMPANHAMENTO!H:H,PJ_B1!$R$1,ACOMPANHAMENTO!BC:BC,PJ_B1!B28,ACOMPANHAMENTO!I:I,"="&"Business Banking 1") -> 0 | N28: =IFERROR(M28/I28,0) -> 0 | O28: =IFERROR(IF(I28/G28=0,"-",I28/G28),"-") -> - | P28: =IFERROR(SUMIFS('HORA HORA'!$K:$K,'HORA HORA'!$B:$B,PJ_B1!$B28,'HORA HORA'!$C:$C,"="&"PJ",'HORA HORA'!$Y:$Y,"<>"&"EMPRESAS_2")/SUMIFS('HORA HORA'!$J:$J,'HORA HORA'!$B:$B,PJ_B1!$B28,'HORA HORA'!$C:$C,"="&"PJ",'HORA HORA'!$Y:$Y,"<>"&"EMPRESAS_2"),0) -> 0 | Q28: =IFERROR(J28/I28,"-") -> -
B29: 46283 | C29: =D29/$A$7 -> 0 | D29: =SUMIFS(TEMPOS!AL:AL,TEMPOS!X:X,$R$2,TEMPOS!Y:Y,B29) -> 0 | E29: =SUMIFS('HORA HORA'!G:G,'HORA HORA'!C:C,PJ_B1!$R$1,'HORA HORA'!B:B,PJ_B1!B29,'HORA HORA'!Y:Y,"<>"&"EMPRESAS_2") -> 0 | F29: =SUMIFS('HORA HORA'!H:H,'HORA HORA'!C:C,PJ_B1!$R$1,'HORA HORA'!B:B,PJ_B1!B29,'HORA HORA'!Y:Y,"<>"&"EMPRESAS_2") -> 0 | G29: =SUMIFS('HORA HORA'!J:J,'HORA HORA'!C:C,PJ_B1!$R$1,'HORA HORA'!B:B,PJ_B1!B29,'HORA HORA'!Y:Y,"<>"&"EMPRESAS_2") -> 0 | H29: =SUMIFS('HORA HORA'!K:K,'HORA HORA'!C:C,PJ_B1!$R$1,'HORA HORA'!B:B,PJ_B1!B29,'HORA HORA'!Y:Y,"<>"&"EMPRESAS_2") -> 0 | I29: =SUMIFS('HORA HORA'!L:L,'HORA HORA'!C:C,PJ_B1!$R$1,'HORA HORA'!B:B,PJ_B1!B29,'HORA HORA'!Y:Y,"<>"&"EMPRESAS_2") -> 0 | J29: =COUNTIFS(ACOMPANHAMENTO!S:S,"ACORDO IMPLANTADO",ACOMPANHAMENTO!BC:BC,B29,ACOMPANHAMENTO!H:H,PJ_B1!$R$1,ACOMPANHAMENTO!I:I,"="&"Business Banking 1") -> 0 | K29: =SUMIFS(ACOMPANHAMENTO!O:O,ACOMPANHAMENTO!H:H,PJ_B1!$R$1,ACOMPANHAMENTO!BC:BC,PJ_B1!B29,ACOMPANHAMENTO!I:I,"="&"Business Banking 1") -> 0 | L29: =IFERROR(K29/I29,0) -> 0 | M29: =SUMIFS(ACOMPANHAMENTO!R:R,ACOMPANHAMENTO!H:H,PJ_B1!$R$1,ACOMPANHAMENTO!BC:BC,PJ_B1!B29,ACOMPANHAMENTO!I:I,"="&"Business Banking 1") -> 0 | N29: =IFERROR(M29/I29,0) -> 0 | O29: =IFERROR(IF(I29/G29=0,"-",I29/G29),"-") -> - | P29: =IFERROR(SUMIFS('HORA HORA'!$K:$K,'HORA HORA'!$B:$B,PJ_B1!$B29,'HORA HORA'!$C:$C,"="&"PJ",'HORA HORA'!$Y:$Y,"<>"&"EMPRESAS_2")/SUMIFS('HORA HORA'!$J:$J,'HORA HORA'!$B:$B,PJ_B1!$B29,'HORA HORA'!$C:$C,"="&"PJ",'HORA HORA'!$Y:$Y,"<>"&"EMPRESAS_2"),0) -> 0 | Q29: =IFERROR(J29/I29,"-") -> -
... B37: 46295 | C37: =D37/$A$7 -> 0 | D37: =SUMIFS(TEMPOS!AL:AL,TEMPOS!X:X,$R$2,TEMPOS!Y:Y,B37) -> 0 | E37: =SUMIFS('HORA HORA'!G:G,'HORA HORA'!C:C,PJ_B1!$R$1,'HORA HORA'!B:B,PJ_B1!B37,'HORA HORA'!Y:Y,"<>"&"EMPRESAS_2") -> 0 | F37: =SUMIFS('HORA HORA'!H:H,'HORA HORA'!C:C,PJ_B1!$R$1,'HORA HORA'!B:B,PJ_B1!B37,'HORA HORA'!Y:Y,"<>"&"EMPRESAS_2") -> 0 | G37: =SUMIFS('HORA HORA'!J:J,'HORA HORA'!C:C,PJ_B1!$R$1,'HORA HORA'!B:B,PJ_B1!B37,'HORA HORA'!Y:Y,"<>"&"EMPRESAS_2") -> 0 | H37: =SUMIFS('HORA HORA'!K:K,'HORA HORA'!C:C,PJ_B1!$R$1,'HORA HORA'!B:B,PJ_B1!B37,'HORA HORA'!Y:Y,"<>"&"EMPRESAS_2") -> 0 | I37: =SUMIFS('HORA HORA'!L:L,'HORA HORA'!C:C,PJ_B1!$R$1,'HORA HORA'!B:B,PJ_B1!B37,'HORA HORA'!Y:Y,"<>"&"EMPRESAS_2") -> 0 | J37: =COUNTIFS(ACOMPANHAMENTO!S:S,"ACORDO IMPLANTADO",ACOMPANHAMENTO!BC:BC,B37,ACOMPANHAMENTO!H:H,PJ_B1!$R$1,ACOMPANHAMENTO!I:I,"="&"Business Banking 1") -> 0 | K37: =SUMIFS(ACOMPANHAMENTO!O:O,ACOMPANHAMENTO!H:H,PJ_B1!$R$1,ACOMPANHAMENTO!BC:BC,PJ_B1!B37,ACOMPANHAMENTO!I:I,"="&"Business Banking 1") -> 0 | L37: =IFERROR(K37/I37,0) -> 0 | M37: =SUMIFS(ACOMPANHAMENTO!R:R,ACOMPANHAMENTO!H:H,PJ_B1!$R$1,ACOMPANHAMENTO!BC:BC,PJ_B1!B37,ACOMPANHAMENTO!I:I,"="&"Business Banking 1") -> 0 | N37: =IFERROR(M37/I37,0) -> 0 | O37: =IFERROR(IF(I37/G37=0,"-",I37/G37),"-") -> - | P37: =IFERROR(SUMIFS('HORA HORA'!$K:$K,'HORA HORA'!$B:$B,PJ_B1!$B37,'HORA HORA'!$C:$C,"="&"PJ",'HORA HORA'!$Y:$Y,"<>"&"EMPRESAS_2")/SUMIFS('HORA HORA'!$J:$J,'HORA HORA'!$B:$B,PJ_B1!$B37,'HORA HORA'!$C:$C,"="&"PJ",'HORA HORA'!$Y:$Y,"<>"&"EMPRESAS_2"),0) -> 0 | Q37: =IFERROR(J37/I37,"-") -> -

Sheet PJ_B2
A1: X' | R1: PJ
I2: Business Banking 2 | R2: B2
B6: DIA | C6: CAPACITY | D6: TEMPO DISP | E6: DISCAGEM | F6: ATENDIDA | G6: CPC | H6: CPCA | I6: PROPOSTA | J6: PAGAMENTO | K6: ($) CASH | L6: ($) TKT CASH | M6: ($) CONTABIL | N6: ($) TKT CONTABIL | O6: (%) CONVERSÃO | P6: =AUX!B11 -> (%) CPC | Q6: (%) EFETIVIDADE
A7: 0.27222222 | C7: =AVERAGE(C9) -> 3 | D7: =A7*4 -> 1.0888889 | E7: 4528 | F7: 106 | G7: 5 | H7: 4 | I7: 2 | J7: 1 | K7: =AUX!C31 -> 52471.543 | L7: =AUX!C32 -> 26235.771 | M7: =AUX!C33 -> 1282413.6 | N7: =AUX!C34 -> 320603.39 | O7: =AUX!C35 -> 0.43 | P7: =AUX!C36 -> 0.58 | Q7: =AUX!C37 -> 0.46
A9: 8 | B9: META GERAL | C9: 3 | D9: =D7*A9 -> 8.7111111 | E9: =E7*A9 -> 36224 | F9: =F7*A9 -> 848 | G9: =G7*A9 -> 40 | H9: =H7*A9 -> 32 | I9: =I7*A9 -> 16 | J9: =J7*A9 -> 8 | K9: 1245000 | L9: =L7 -> 26235.771 | M9: 10200000 | N9: =N7 -> 320603.39 | O9: =O7 -> 0.43 | P9: =P7 -> 0.58 | Q9: =Q7 -> 0.46
B10: REALIZADO | C10: =AVERAGE(C17:C24) -> 1.0909823 | D10: =SUM(D17:D37) -> 2.375917 | E10: =SUM(E17:E34) -> 57210 | F10: =SUM(F17:F37) -> 1229 | G10: =SUM(G17:G37) -> 105 | H10: =SUM(H17:H34) -> 89 | I10: =SUM(I17:I37) -> 30 | J10: =SUM(J17:J37) -> 6 | K10: =SUM(K17:K37) -> 182711.71 | L10: =IFERROR(K10/J10,0) -> 30451.952 | M10: =SUM(M17:M37) -> 760855.69 | N10: =IFERROR(M10/J10,0) -> 126809.28 | O10: =AVERAGE(O17:O36) -> 0.27411183 | P10: =IFERROR(AVERAGE(P17:P24),0) -> 0.82964223 | Q10: =AVERAGE(Q17:Q37) -> 0.21994048
B11: META RELOGIO | C11: - | D11: =D7*(COUNTIFS(D17:D34,">="&0)) -> 19.6 | E11: =E7*(COUNTIFS(E17:E33,">="&1)) -> 36224 | F11: =F7*(COUNTIFS(F17:F33,">="&1)) -> 848 | G11: =G7*(COUNTIFS(G16:G30,">="&1)) -> 40 | H11: =H7*(COUNTIFS(H17:H34,">="&1)) -> 32 | I11: =I7*(COUNTIFS(I17:I34,">="&1)) -> 16 | J11: =J7*(COUNTIFS(J16:J33,">="&1)) -> 5 | K11: =K7*(COUNTIFS(K16:K34,">="&1)) -> 262357.71 | L11: =L9 -> 26235.771 | M11: =M7*(COUNTIFS(M16:M34,">="&1)) -> 6412067.8 | N11: =N9 -> 320603.39 | O11: =O9 -> 0.43 | P11: =P9 -> 0.58 | Q11: =Q9 -> 0.46
B13: (%) META REALIZADO | C13: =C10/C9 -> 0.36366077 | E13: =E10/E9 -> 1.5793397 | F13: =F10/F9 -> 1.4492925 | G13: =G10/G9 -> 2.625 | H13: =H10/H9 -> 2.78125 | I13: =I10/I9 -> 1.875 | J13: =J10/J9 -> 0.75 | K13: =K10/K9 -> 0.14675639 | L13: =L10/L9 -> 1.1607035 | ... Q13: =Q10/Q9 -> 0.47813147
B14: (%) META RELOGIO | C14: - | E14: =E10/E11 -> 1.5793397 | F14: =F10/F11 -> 1.4492925 | G14: =G10/G11 -> 2.625 | H14: =H10/H11 -> 2.78125 | I14: =I10/I11 -> 1.875 | J14: =IFERROR(J10/J11,0) -> 1.2 | K14: =IFERROR(K10/K11,0) -> 0.6964221 | L14: =L10/L11 -> 1.1607035 | M14: =IFERROR(M10/M11,0) -> 0.11865996 | N14: =N10/N11 -> 0.39553319 | O14: =O10/O11 -> 0.63746936 | P14: =P10/P11 -> 1.4304176 | Q14: =Q10/Q11 -> 0.47813147
B16: DATA | C16: REALIZADO | D16: TEMPO REALIZADO | E16: DISCAGEM | F16: ATENDIDA | G16: CPC | H16: CPCA | I16: PROPOSTA | J16: PAGAMENTO | K16: ($) CASH | L16: ($) TKT CASH | M16: ($) CONTABIL | N16: ($) TKT CONTABIL | O16: (%) CONVERSÃO | P16: (%) CPC | Q16: (%) EFETIVIDADE
B17: 46266 | C17: =D17/$A$7 -> 0.64153469 | D17: =SUMIFS(TEMPOS!AL:AL,TEMPOS!X:X,$R$2,TEMPOS!Y:Y,B17) -> 0.17464 | E17: =SUMIFS('HORA HORA'!G:G,'HORA HORA'!C:C,PJ_B2!$R$1,'HORA HORA'!B:B,PJ_B2!B17,'HORA HORA'!Y:Y,"="&"EMPRESAS_2") -> 5059 | F17: =SUMIFS('HORA HORA'!H:H,'HORA HORA'!C:C,PJ_B2!$R$1,'HORA HORA'!B:B,PJ_B2!B17,'HORA HORA'!Y:Y,"="&"EMPRESAS_2") -> 136 | G17: =SUMIFS('HORA HORA'!J:J,'HORA HORA'!C:C,PJ_B2!$R$1,'HORA HORA'!B:B,PJ_B2!B17,'HORA HORA'!Y:Y,"="&"EMPRESAS_2") -> 16 | H17: =SUMIFS('HORA HORA'!K:K,'HORA HORA'!C:C,PJ_B2!$R$1,'HORA HORA'!B:B,PJ_B2!B17,'HORA HORA'!Y:Y,"="&"EMPRESAS_2") -> 16 | I17: =SUMIFS('HORA HORA'!L:L,'HORA HORA'!C:C,PJ_B2!$R$1,'HORA HORA'!B:B,PJ_B2!B17,'HORA HORA'!Y:Y,"="&"EMPRESAS_2") -> 5 | J17: =COUNTIFS(ACOMPANHAMENTO!S:S,"ACORDO IMPLANTADO",ACOMPANHAMENTO!BC:BC,B17,ACOMPANHAMENTO!H:H,PJ_B2!$R$1,ACOMPANHAMENTO!I:I,"="&"Business Banking 2") -> 1 | K17: =SUMIFS(ACOMPANHAMENTO!O:O,ACOMPANHAMENTO!H:H,PJ_B1!$R$1,ACOMPANHAMENTO!BC:BC,PJ_B1!B17,ACOMPANHAMENTO!I:I,"="&"Business Banking 2") -> 57697.26 | L17: =K17/I17 -> 11539.452 | M17: =SUMIFS(ACOMPANHAMENTO!R:R,ACOMPANHAMENTO!H:H,PJ_B1!$R$1,ACOMPANHAMENTO!BC:BC,PJ_B2!B17,ACOMPANHAMENTO!I:I,"="&"Business Banking 2") -> 354701.99 | N17: =M17/I17 -> 70940.398 | O17: =IFERROR(IF(I17/G17=0,"-",I17/G17),"-") -> 0.3125 | P17: =SUMIFS('HORA HORA'!$K:$K,'HORA HORA'!$B:$B,PJ_B2!$B17,'HORA HORA'!$C:$C,"="&"PJ",'HORA HORA'!$Y:$Y,"="&"EMPRESAS_2")/SUMIFS('HORA HORA'!$J:$J,'HORA HORA'!$B:$B,PJ_B1!$B17,'HORA HORA'!$C:$C,"="&"PJ",'HORA HORA'!$Y:$Y,"="&"EMPRESAS_2") -> 1 | Q17: =IFERROR(J17/I17,"-") -> 0.2
B18: 46267 | C18: =D18/$A$7 -> 1.5763629 | D18: =SUMIFS(TEMPOS!AL:AL,TEMPOS!X:X,$R$2,TEMPOS!Y:Y,B18) -> 0.429121 | E18: =SUMIFS('HORA HORA'!G:G,'HORA HORA'!C:C,PJ_B2!$R$1,'HORA HORA'!B:B,PJ_B2!B18,'HORA HORA'!Y:Y,"="&"EMPRESAS_2") -> 8044 | F18: =SUMIFS('HORA HORA'!H:H,'HORA HORA'!C:C,PJ_B2!$R$1,'HORA HORA'!B:B,PJ_B2!B18,'HORA HORA'!Y:Y,"="&"EMPRESAS_2") -> 208 | G18: =SUMIFS('HORA HORA'!J:J,'HORA HORA'!C:C,PJ_B2!$R$1,'HORA HORA'!B:B,PJ_B2!B18,'HORA HORA'!Y:Y,"="&"EMPRESAS_2") -> 13 | H18: =SUMIFS('HORA HORA'!K:K,'HORA HORA'!C:C,PJ_B2!$R$1,'HORA HORA'!B:B,PJ_B2!B18,'HORA HORA'!Y:Y,"="&"EMPRESAS_2") -> 12 | I18: =SUMIFS('HORA HORA'!L:L,'HORA HORA'!C:C,PJ_B2!$R$1,'HORA HORA'!B:B,PJ_B2!B18,'HORA HORA'!Y:Y,"="&"EMPRESAS_2") -> 3 | J18: =COUNTIFS(ACOMPANHAMENTO!S:S,"ACORDO IMPLANTADO",ACOMPANHAMENTO!BC:BC,B18,ACOMPANHAMENTO!H:H,PJ_B2!$R$1,ACOMPANHAMENTO!I:I,"="&"Business Banking 2") -> 0 | K18: =SUMIFS(ACOMPANHAMENTO!O:O,ACOMPANHAMENTO!H:H,PJ_B1!$R$1,ACOMPANHAMENTO!BC:BC,PJ_B1!B18,ACOMPANHAMENTO!I:I,"="&"Business Banking 2") -> 0 | L18: =IFERROR(K18/I18,0) -> 0 | M18: =SUMIFS(ACOMPANHAMENTO!R:R,ACOMPANHAMENTO!H:H,PJ_B1!$R$1,ACOMPANHAMENTO!BC:BC,PJ_B2!B18,ACOMPANHAMENTO!I:I,"="&"Business Banking 2") -> 0 | N18: =IFERROR(M18/I18,0) -> 0 | O18: =IFERROR(IF(I18/G18=0,"-",I18/G18),"-") -> 0.23076923 | P18: =SUMIFS('HORA HORA'!$K:$K,'HORA HORA'!$B:$B,PJ_B2!$B18,'HORA HORA'!$C:$C,"="&"PJ",'HORA HORA'!$Y:$Y,"="&"EMPRESAS_2")/SUMIFS('HORA HORA'!$J:$J,'HORA HORA'!$B:$B,PJ_B1!$B18,'HORA HORA'!$C:$C,"="&"PJ",'HORA HORA'!$Y:$Y,"="&"EMPRESAS_2") -> 0.92307692 | Q18: =IFERROR(J18/I18,"-") -> 0
B19: 46268 | C19: =D19/$A$7 -> 1.1154343 | D19: =SUMIFS(TEMPOS!AL:AL,TEMPOS!X:X,$R$2,TEMPOS!Y:Y,B19) -> 0.303646 | E19: =SUMIFS('HORA HORA'!G:G,'HORA HORA'!C:C,PJ_B2!$R$1,'HORA HORA'!B:B,PJ_B2!B19,'HORA HORA'!Y:Y,"="&"EMPRESAS_2") -> 7599 | F19: =SUMIFS('HORA HORA'!H:H,'HORA HORA'!C:C,PJ_B2!$R$1,'HORA HORA'!B:B,PJ_B2!B19,'HORA HORA'!Y:Y,"="&"EMPRESAS_2") -> 210 | G19: =SUMIFS('HORA HORA'!J:J,'HORA HORA'!C:C,PJ_B2!$R$1,'HORA HORA'!B:B,PJ_B2!B19,'HORA HORA'!Y:Y,"="&"EMPRESAS_2") -> 14 | H19: =SUMIFS('HORA HORA'!K:K,'HORA HORA'!C:C,PJ_B2!$R$1,'HORA HORA'!B:B,PJ_B2!B19,'HORA HORA'!Y:Y,"="&"EMPRESAS_2") -> 13 | I19: =SUMIFS('HORA HORA'!L:L,'HORA HORA'!C:C,PJ_B2!$R$1,'HORA HORA'!B:B,PJ_B2!B19,'HORA HORA'!Y:Y,"="&"EMPRESAS_2") -> 5 | J19: =COUNTIFS(ACOMPANHAMENTO!S:S,"ACORDO IMPLANTADO",ACOMPANHAMENTO!BC:BC,B19,ACOMPANHAMENTO!H:H,PJ_B2!$R$1,ACOMPANHAMENTO!I:I,"="&"Business Banking 2") -> 0 | K19: =SUMIFS(ACOMPANHAMENTO!O:O,ACOMPANHAMENTO!H:H,PJ_B1!$R$1,ACOMPANHAMENTO!BC:BC,PJ_B1!B19,ACOMPANHAMENTO!I:I,"="&"Business Banking 2") -> 0 | L19: =IFERROR(K19/I19,0) -> 0 | M19: =SUMIFS(ACOMPANHAMENTO!R:R,ACOMPANHAMENTO!H:H,PJ_B1!$R$1,ACOMPANHAMENTO!BC:BC,PJ_B2!B19,ACOMPANHAMENTO!I:I,"="&"Business Banking 2") -> 0 | N19: =IFERROR(M19/I19,0) -> 0 | O19: =IFERROR(IF(I19/G19=0,"-",I19/G19),"-") -> 0.35714286 | P19: =SUMIFS('HORA HORA'!$K:$K,'HORA HORA'!$B:$B,PJ_B1!$B19,'HORA HORA'!$C:$C,"="&"PJ",'HORA HORA'!$Y:$Y,"="&"EMPRESAS_2")/SUMIFS('HORA HORA'!$J:$J,'HORA HORA'!$B:$B,PJ_B2!$B19,'HORA HORA'!$C:$C,"="&"PJ",'HORA HORA'!$Y:$Y,"="&"EMPRESAS_2") -> 0.92857143 | Q19: =IFERROR(J19/I19,"-") -> 0
B20: 46269 | C20: =D20/$A$7 -> 1.3118694 | D20: =SUMIFS(TEMPOS!AL:AL,TEMPOS!X:X,$R$2,TEMPOS!Y:Y,B20) -> 0.35712 | E20: =SUMIFS('HORA HORA'!G:G,'HORA HORA'!C:C,PJ_B2!$R$1,'HORA HORA'!B:B,PJ_B2!B20,'HORA HORA'!Y:Y,"="&"EMPRESAS_2") -> 5941 | F20: =SUMIFS('HORA HORA'!H:H,'HORA HORA'!C:C,PJ_B2!$R$1,'HORA HORA'!B:B,PJ_B2!B20,'HORA HORA'!Y:Y,"="&"EMPRESAS_2") -> 113 | G20: =SUMIFS('HORA HORA'!J:J,'HORA HORA'!C:C,PJ_B2!$R$1,'HORA HORA'!B:B,PJ_B2!B20,'HORA HORA'!Y:Y,"="&"EMPRESAS_2") -> 8 | H20: =SUMIFS('HORA HORA'!K:K,'HORA HORA'!C:C,PJ_B2!$R$1,'HORA HORA'!B:B,PJ_B2!B20,'HORA HORA'!Y:Y,"="&"EMPRESAS_2") -> 5 | I20: =SUMIFS('HORA HORA'!L:L,'HORA HORA'!C:C,PJ_B2!$R$1,'HORA HORA'!B:B,PJ_B2!B20,'HORA HORA'!Y:Y,"="&"EMPRESAS_2") -> 1 | J20: =COUNTIFS(ACOMPANHAMENTO!S:S,"ACORDO IMPLANTADO",ACOMPANHAMENTO!BC:BC,B20,ACOMPANHAMENTO!H:H,PJ_B2!$R$1,ACOMPANHAMENTO!I:I,"="&"Business Banking 2") -> 0 | K20: =SUMIFS(ACOMPANHAMENTO!O:O,ACOMPANHAMENTO!H:H,PJ_B1!$R$1,ACOMPANHAMENTO!BC:BC,PJ_B1!#REF!,ACOMPANHAMENTO!I:I,"="&"Business Banking 2") -> 0 | L20: =IFERROR(K20/I20,0) -> 0 | M20: =SUMIFS(ACOMPANHAMENTO!R:R,ACOMPANHAMENTO!H:H,PJ_B1!$R$1,ACOMPANHAMENTO!BC:BC,PJ_B2!B20,ACOMPANHAMENTO!I:I,"="&"Business Banking 2") -> 0 | N20: =IFERROR(M20/I20,0) -> 0 | O20: =IFERROR(IF(I20/G20=0,"-",I20/G20),"-") -> 0.125 | P20: =SUMIFS('HORA HORA'!$K:$K,'HORA HORA'!$B:$B,PJ_B1!$B20,'HORA HORA'!$C:$C,"="&"PJ",'HORA HORA'!$Y:$Y,"="&"EMPRESAS_2")/SUMIFS('HORA HORA'!$J:$J,'HORA HORA'!$B:$B,PJ_B1!$B20,'HORA HORA'!$C:$C,"="&"PJ",'HORA HORA'!$Y:$Y,"="&"EMPRESAS_2") -> 0.625 | Q20: =IFERROR(J20/I20,"-") -> 0
B21: 46273 | C21: =D21/$A$7 -> 1.5344816 | D21: =SUMIFS(TEMPOS!AL:AL,TEMPOS!X:X,$R$2,TEMPOS!Y:Y,B21) -> 0.41772 | E21: =SUMIFS('HORA HORA'!G:G,'HORA HORA'!C:C,PJ_B2!$R$1,'HORA HORA'!B:B,PJ_B2!B21,'HORA HORA'!Y:Y,"="&"EMPRESAS_2") -> 6960 | F21: =SUMIFS('HORA HORA'!H:H,'HORA HORA'!C:C,PJ_B2!$R$1,'HORA HORA'!B:B,PJ_B2!B21,'HORA HORA'!Y:Y,"="&"EMPRESAS_2") -> 130 | G21: =SUMIFS('HORA HORA'!J:J,'HORA HORA'!C:C,PJ_B2!$R$1,'HORA HORA'!B:B,PJ_B2!B21,'HORA HORA'!Y:Y,"="&"EMPRESAS_2") -> 20 | H21: =SUMIFS('HORA HORA'!K:K,'HORA HORA'!C:C,PJ_B2!$R$1,'HORA HORA'!B:B,PJ_B2!B21,'HORA HORA'!Y:Y,"="&"EMPRESAS_2") -> 17 | I21: =SUMIFS('HORA HORA'!L:L,'HORA HORA'!C:C,PJ_B2!$R$1,'HORA HORA'!B:B,PJ_B2!B21,'HORA HORA'!Y:Y,"="&"EMPRESAS_2") -> 7 | J21: =COUNTIFS(ACOMPANHAMENTO!S:S,"ACORDO IMPLANTADO",ACOMPANHAMENTO!BC:BC,B21,ACOMPANHAMENTO!H:H,PJ_B2!$R$1,ACOMPANHAMENTO!I:I,"="&"Business Banking 2") -> 1 | K21: =SUMIFS(ACOMPANHAMENTO!O:O,ACOMPANHAMENTO!H:H,PJ_B1!$R$1,ACOMPANHAMENTO!BC:BC,PJ_B1!#REF!,ACOMPANHAMENTO!I:I,"="&"Business Banking 2") -> 0 | L21: =IFERROR(K21/I21,0) -> 0 | M21: =SUMIFS(ACOMPANHAMENTO!R:R,ACOMPANHAMENTO!H:H,PJ_B1!$R$1,ACOMPANHAMENTO!BC:BC,PJ_B2!B21,ACOMPANHAMENTO!I:I,"="&"Business Banking 2") -> 33523.07 | N21: =IFERROR(M21/I21,0) -> 4789.01 | O21: =IFERROR(IF(I21/G21=0,"-",I21/G21),"-") -> 0.35 | P21: =SUMIFS('HORA HORA'!$K:$K,'HORA HORA'!$B:$B,PJ_B2!$B21,'HORA HORA'!$C:$C,"="&"PJ",'HORA HORA'!$Y:$Y,"="&"EMPRESAS_2")/SUMIFS('HORA HORA'!$J:$J,'HORA HORA'!$B:$B,PJ_B2!$B21,'HORA HORA'!$C:$C,"="&"PJ",'HORA HORA'!$Y:$Y,"="&"EMPRESAS_2") -> 0.85 | Q21: =IFERROR(J21/I21,"-") -> 0.14285714
B22: 46274 | C22: =D22/$A$7 -> 1.8583788 | D22: =SUMIFS(TEMPOS!AL:AL,TEMPOS!X:X,$R$2,TEMPOS!Y:Y,B22) -> 0.505892 | E22: =SUMIFS('HORA HORA'!G:G,'HORA HORA'!C:C,PJ_B2!$R$1,'HORA HORA'!B:B,PJ_B2!B22,'HORA HORA'!Y:Y,"="&"EMPRESAS_2") -> 9155 | F22: =SUMIFS('HORA HORA'!H:H,'HORA HORA'!C:C,PJ_B2!$R$1,'HORA HORA'!B:B,PJ_B2!B22,'HORA HORA'!Y:Y,"="&"EMPRESAS_2") -> 179 | G22: =SUMIFS('HORA HORA'!J:J,'HORA HORA'!C:C,PJ_B2!$R$1,'HORA HORA'!B:B,PJ_B2!B22,'HORA HORA'!Y:Y,"="&"EMPRESAS_2") -> 13 | H22: =SUMIFS('HORA HORA'!K:K,'HORA HORA'!C:C,PJ_B2!$R$1,'HORA HORA'!B:B,PJ_B2!B22,'HORA HORA'!Y:Y,"="&"EMPRESAS_2") -> 9 | I22: =SUMIFS('HORA HORA'!L:L,'HORA HORA'!C:C,PJ_B2!$R$1,'HORA HORA'!B:B,PJ_B2!B22,'HORA HORA'!Y:Y,"="&"EMPRESAS_2") -> 2 | J22: =COUNTIFS(ACOMPANHAMENTO!S:S,"ACORDO IMPLANTADO",ACOMPANHAMENTO!BC:BC,B22,ACOMPANHAMENTO!H:H,PJ_B2!$R$1,ACOMPANHAMENTO!I:I,"="&"Business Banking 2") -> 1 | K22: =SUMIFS(ACOMPANHAMENTO!O:O,ACOMPANHAMENTO!H:H,PJ_B1!$R$1,ACOMPANHAMENTO!BC:BC,PJ_B1!B21,ACOMPANHAMENTO!I:I,"="&"Business Banking 2") -> 85000 | L22: =IFERROR(K22/I22,0) -> 42500 | M22: =SUMIFS(ACOMPANHAMENTO!R:R,ACOMPANHAMENTO!H:H,PJ_B1!$R$1,ACOMPANHAMENTO!BC:BC,PJ_B2!B22,ACOMPANHAMENTO!I:I,"="&"Business Banking 2") -> 21086.32 | N22: =IFERROR(M22/I22,0) -> 10543.16 | O22: =IFERROR(IF(I22/G22=0,"-",I22/G22),"-") -> 0.15384615 | P22: =SUMIFS('HORA HORA'!$K:$K,'HORA HORA'!$B:$B,PJ_B2!$B22,'HORA HORA'!$C:$C,"="&"PJ",'HORA HORA'!$Y:$Y,"="&"EMPRESAS_2")/SUMIFS('HORA HORA'!$J:$J,'HORA HORA'!$B:$B,PJ_B2!$B22,'HORA HORA'!$C:$C,"="&"PJ",'HORA HORA'!$Y:$Y,"="&"EMPRESAS_2") -> 0.69230769 | Q22: =IFERROR(J22/I22,"-") -> 0.5
